Workbook

Sheet Summary
D2: Seleccione Canal
AH3: Chat | AI3: 2 | AJ3: =IF(AI3=1,AH3,IF(AI3=2,AH4,"")) -> Voz
AH4: Voz
C21: Lunes | D21: Martes | E21: Miércoles | F21: Jueves | G21: Viernes | H21: Sábado | I21: Domingo | J21: Total
B22: Llamadas Pronosticadas | C22: =SUMIFS(BBDD!$E:$E,BBDD!$C:$C,Summary!C$21,BBDD!$B:$B,Summary!$AJ$3) -> 376 | D22: =SUMIFS(BBDD!$E:$E,BBDD!$C:$C,Summary!D$21,BBDD!$B:$B,Summary!$AJ$3) -> 391 | E22: =SUMIFS(BBDD!$E:$E,BBDD!$C:$C,Summary!E$21,BBDD!$B:$B,Summary!$AJ$3) -> 359 | F22: =SUMIFS(BBDD!$E:$E,BBDD!$C:$C,Summary!F$21,BBDD!$B:$B,Summary!$AJ$3) -> 349 | G22: =SUMIFS(BBDD!$E:$E,BBDD!$C:$C,Summary!G$21,BBDD!$B:$B,Summary!$AJ$3) -> 274 | H22: =SUMIFS(BBDD!$E:$E,BBDD!$C:$C,Summary!H$21,BBDD!$B:$B,Summary!$AJ$3) -> 164 | I22: =SUMIFS(BBDD!$E:$E,BBDD!$C:$C,Summary!I$21,BBDD!$B:$B,Summary!$AJ$3) -> 16 | J22: =SUM(C22:I22) -> 1929
B23: TMO (seg.) | C23: =SUMIFS(BBDD!$F:$F,BBDD!$C:$C,Summary!C$21,BBDD!$B:$B,Summary!$AJ$3)/COUNTIFS(BBDD!$F:$F,">"&0,BBDD!$C:$C,Summary!C$21,BBDD!$B:$B,Summary!$AJ$3) -> 660 | D23: =SUMIFS(BBDD!$F:$F,BBDD!$C:$C,Summary!D$21,BBDD!$B:$B,Summary!$AJ$3)/COUNTIFS(BBDD!$F:$F,">"&0,BBDD!$C:$C,Summary!D$21,BBDD!$B:$B,Summary!$AJ$3) -> 660 | E23: =SUMIFS(BBDD!$F:$F,BBDD!$C:$C,Summary!E$21,BBDD!$B:$B,Summary!$AJ$3)/COUNTIFS(BBDD!$F:$F,">"&0,BBDD!$C:$C,Summary!E$21,BBDD!$B:$B,Summary!$AJ$3) -> 660 | F23: =SUMIFS(BBDD!$F:$F,BBDD!$C:$C,Summary!F$21,BBDD!$B:$B,Summary!$AJ$3)/COUNTIFS(BBDD!$F:$F,">"&0,BBDD!$C:$C,Summary!F$21,BBDD!$B:$B,Summary!$AJ$3) -> 660 | G23: =SUMIFS(BBDD!$F:$F,BBDD!$C:$C,Summary!G$21,BBDD!$B:$B,Summary!$AJ$3)/COUNTIFS(BBDD!$F:$F,">"&0,BBDD!$C:$C,Summary!G$21,BBDD!$B:$B,Summary!$AJ$3) -> 740 | H23: =SUMIFS(BBDD!$F:$F,BBDD!$C:$C,Summary!H$21,BBDD!$B:$B,Summary!$AJ$3)/COUNTIFS(BBDD!$F:$F,">"&0,BBDD!$C:$C,Summary!H$21,BBDD!$B:$B,Summary!$AJ$3) -> 740 | I23: =SUMIFS(BBDD!$F:$F,BBDD!$C:$C,Summary!I$21,BBDD!$B:$B,Summary!$AJ$3)/COUNTIFS(BBDD!$F:$F,">"&0,BBDD!$C:$C,Summary!I$21,BBDD!$B:$B,Summary!$AJ$3) -> 740 | J23: =SUMPRODUCT(C23:I23,C22:I22)/J22 -> 678.82841
B24: Asesores Requeridos | C24: =SUMIFS(BBDD!$J:$J,BBDD!$C:$C,Summary!C$21,BBDD!$B:$B,Summary!$AJ$3)/15 -> 15.8 | D24: =SUMIFS(BBDD!$J:$J,BBDD!$C:$C,Summary!D$21,BBDD!$B:$B,Summary!$AJ$3)/15 -> 15.333333 | E24: =SUMIFS(BBDD!$J:$J,BBDD!$C:$C,Summary!E$21,BBDD!$B:$B,Summary!$AJ$3)/15 -> 14.866667 | F24: =SUMIFS(BBDD!$J:$J,BBDD!$C:$C,Summary!F$21,BBDD!$B:$B,Summary!$AJ$3)/15 -> 14.4 | G24: =SUMIFS(BBDD!$J:$J,BBDD!$C:$C,Summary!G$21,BBDD!$B:$B,Summary!$AJ$3)/15 -> 13.266667 | H24: =SUMIFS(BBDD!$J:$J,BBDD!$C:$C,Summary!H$21,BBDD!$B:$B,Summary!$AJ$3)/15 -> 9.2666667 | I24: =SUMIFS(BBDD!$J:$J,BBDD!$C:$C,Summary!I$21,BBDD!$B:$B,Summary!$AJ$3)/15 -> 3.2 | J24: =SUM(C24:I24)/7 -> 12.304762
B25: % Reductor | C25: 0.1 | D25: 0.1 | E25: 0.1 | F25: 0.1 | G25: 0.1 | H25: 0.1 | I25: 0.1 | J25: 0.1
B26: Ases. Req con Reductores | C26: =SUMIFS(BBDD!$L:$L,BBDD!$C:$C,Summary!C$21,BBDD!$B:$B,Summary!$AJ$3)/15 -> 18.8 | D26: =SUMIFS(BBDD!$L:$L,BBDD!$C:$C,Summary!D$21,BBDD!$B:$B,Summary!$AJ$3)/15 -> 17.466667 | E26: =SUMIFS(BBDD!$L:$L,BBDD!$C:$C,Summary!E$21,BBDD!$B:$B,Summary!$AJ$3)/15 -> 14.866667 | F26: =SUMIFS(BBDD!$L:$L,BBDD!$C:$C,Summary!F$21,BBDD!$B:$B,Summary!$AJ$3)/15 -> 16.866667 | G26: =SUMIFS(BBDD!$L:$L,BBDD!$C:$C,Summary!G$21,BBDD!$B:$B,Summary!$AJ$3)/15 -> 15.8 | H26: =SUMIFS(BBDD!$L:$L,BBDD!$C:$C,Summary!H$21,BBDD!$B:$B,Summary!$AJ$3)/15 -> 11.6 | I26: =SUMIFS(BBDD!$L:$L,BBDD!$C:$C,Summary!I$21,BBDD!$B:$B,Summary!$AJ$3)/15 -> 5.3333333 | J26: =SUM(C26:I26)/7 -> 14.390476
B27: Asesores Programados | C27: =SUMIFS(BBDD!$M:$M,BBDD!$C:$C,Summary!C$21,BBDD!$B:$B,Summary!$AJ$3)/15 -> 21.733333 | D27: =SUMIFS(BBDD!$M:$M,BBDD!$C:$C,Summary!D$21,BBDD!$B:$B,Summary!$AJ$3)/15 -> 21.933333 | E27: =SUMIFS(BBDD!$M:$M,BBDD!$C:$C,Summary!E$21,BBDD!$B:$B,Summary!$AJ$3)/15 -> 21.666667 | F27: =SUMIFS(BBDD!$M:$M,BBDD!$C:$C,Summary!F$21,BBDD!$B:$B,Summary!$AJ$3)/15 -> 21.666667 | G27: =SUMIFS(BBDD!$M:$M,BBDD!$C:$C,Summary!G$21,BBDD!$B:$B,Summary!$AJ$3)/15 -> 21.6 | H27: =SUMIFS(BBDD!$M:$M,BBDD!$C:$C,Summary!H$21,BBDD!$B:$B,Summary!$AJ$3)/15 -> 12.133333 | I27: =SUMIFS(BBDD!$M:$M,BBDD!$C:$C,Summary!I$21,BBDD!$B:$B,Summary!$AJ$3)/13 -> 4.0384615 | J27: =MAX(C27:I27) -> 21.933333
B28: Diferencia | C28: =+C27-C26 -> 2.9333333 | D28: =+D27-D26 -> 4.4666667 | E28: =+E27-E26 -> 6.8 | F28: =+F27-F26 -> 4.8 | G28: =+G27-G26 -> 5.8 | H28: =+H27-H26 -> 0.53333333 | I28: =+I27-I26 -> -1.2948718 | J28: =SUM(C28:I28)/7 -> 3.4340659
B29: % Nivel Serv. Esperado | C29: =SUMIFS(BBDD!$S:$S,BBDD!$C:$C,Summary!C$21,BBDD!$B:$B,Summary!$AJ$3)/SUMIFS(BBDD!$E:$E,BBDD!$C:$C,Summary!C$21,BBDD!$B:$B,Summary!$AJ$3) -> 0.90389119 | D29: =SUMIFS(BBDD!$S:$S,BBDD!$C:$C,Summary!D$21,BBDD!$B:$B,Summary!$AJ$3)/SUMIFS(BBDD!$E:$E,BBDD!$C:$C,Summary!D$21,BBDD!$B:$B,Summary!$AJ$3) -> 0.88229671 | E29: =SUMIFS(BBDD!$S:$S,BBDD!$C:$C,Summary!E$21,BBDD!$B:$B,Summary!$AJ$3)/SUMIFS(BBDD!$E:$E,BBDD!$C:$C,Summary!E$21,BBDD!$B:$B,Summary!$AJ$3) -> 0.88193076 | F29: =SUMIFS(BBDD!$S:$S,BBDD!$C:$C,Summary!F$21,BBDD!$B:$B,Summary!$AJ$3)/SUMIFS(BBDD!$E:$E,BBDD!$C:$C,Summary!F$21,BBDD!$B:$B,Summary!$AJ$3) -> 0.95137519 | G29: =SUMIFS(BBDD!$S:$S,BBDD!$C:$C,Summary!G$21,BBDD!$B:$B,Summary!$AJ$3)/SUMIFS(BBDD!$E:$E,BBDD!$C:$C,Summary!G$21,BBDD!$B:$B,Summary!$AJ$3) -> 0.96157655 | H29: =SUMIFS(BBDD!$S:$S,BBDD!$C:$C,Summary!H$21,BBDD!$B:$B,Summary!$AJ$3)/SUMIFS(BBDD!$E:$E,BBDD!$C:$C,Summary!H$21,BBDD!$B:$B,Summary!$AJ$3) -> 0.91896955 | I29: =SUMIFS(BBDD!$S:$S,BBDD!$C:$C,Summary!I$21,BBDD!$B:$B,Summary!$AJ$3)/SUMIFS(BBDD!$E:$E,BBDD!$C:$C,Summary!I$21,BBDD!$B:$B,Summary!$AJ$3) -> 0.86740239 | J29: =SUMPRODUCT(C29:I29,C22:I22)/J22 -> 0.91319109
B30: % Nivel Atención | C30: =SUMIFS(BBDD!$T:$T,BBDD!$C:$C,Summary!C$21,BBDD!$B:$B,Summary!$AJ$3)/SUMIFS(BBDD!$E:$E,BBDD!$C:$C,Summary!C$21,BBDD!$B:$B,Summary!$AJ$3) -> 1 | D30: =SUMIFS(BBDD!$T:$T,BBDD!$C:$C,Summary!D$21,BBDD!$B:$B,Summary!$AJ$3)/SUMIFS(BBDD!$E:$E,BBDD!$C:$C,Summary!D$21,BBDD!$B:$B,Summary!$AJ$3) -> 0.9655894 | E30: =SUMIFS(BBDD!$T:$T,BBDD!$C:$C,Summary!E$21,BBDD!$B:$B,Summary!$AJ$3)/SUMIFS(BBDD!$E:$E,BBDD!$C:$C,Summary!E$21,BBDD!$B:$B,Summary!$AJ$3) -> 0.97467713 | F30: =SUMIFS(BBDD!$T:$T,BBDD!$C:$C,Summary!F$21,BBDD!$B:$B,Summary!$AJ$3)/SUMIFS(BBDD!$E:$E,BBDD!$C:$C,Summary!F$21,BBDD!$B:$B,Summary!$AJ$3) -> 0.97861422 | G30: =SUMIFS(BBDD!$T:$T,BBDD!$C:$C,Summary!G$21,BBDD!$B:$B,Summary!$AJ$3)/SUMIFS(BBDD!$E:$E,BBDD!$C:$C,Summary!G$21,BBDD!$B:$B,Summary!$AJ$3) -> 0.97653383 | H30: =SUMIFS(BBDD!$T:$T,BBDD!$C:$C,Summary!H$21,BBDD!$B:$B,Summary!$AJ$3)/SUMIFS(BBDD!$E:$E,BBDD!$C:$C,Summary!H$21,BBDD!$B:$B,Summary!$AJ$3) -> 1 | I30: =SUMIFS(BBDD!$T:$T,BBDD!$C:$C,Summary!I$21,BBDD!$B:$B,Summary!$AJ$3)/SUMIFS(BBDD!$E:$E,BBDD!$C:$C,Summary!I$21,BBDD!$B:$B,Summary!$AJ$3) -> 1 | J30: =SUMPRODUCT(C30:I30,C22:I22)/J22 -> 0.98110999
B31: % Ocupación | C31: =(C$22/IF($AJ$3="Chat",3,1)*C$23)/SUMIFS(BBDD!$U:$U,BBDD!$C:$C,Summary!C$21,BBDD!$B:$B,Summary!$AJ$3) -> 0.42290389 | D31: =(D$22/IF($AJ$3="Chat",3,1)*D$23)/SUMIFS(BBDD!$U:$U,BBDD!$C:$C,Summary!D$21,BBDD!$B:$B,Summary!$AJ$3) -> 0.43576494 | E31: =(E$22/IF($AJ$3="Chat",3,1)*E$23)/SUMIFS(BBDD!$U:$U,BBDD!$C:$C,Summary!E$21,BBDD!$B:$B,Summary!$AJ$3) -> 0.40502564 | F31: =(F$22/IF($AJ$3="Chat",3,1)*F$23)/SUMIFS(BBDD!$U:$U,BBDD!$C:$C,Summary!F$21,BBDD!$B:$B,Summary!$AJ$3) -> 0.39374359 | G31: =(G$22/IF($AJ$3="Chat",3,1)*G$23)/SUMIFS(BBDD!$U:$U,BBDD!$C:$C,Summary!G$21,BBDD!$B:$B,Summary!$AJ$3) -> 0.34766804 | H31: =(H$22/IF($AJ$3="Chat",3,1)*H$23)/SUMIFS(BBDD!$U:$U,BBDD!$C:$C,Summary!H$21,BBDD!$B:$B,Summary!$AJ$3) -> 0.37045177 | I31: =(I$22/IF($AJ$3="Chat",3,1)*I$23)/SUMIFS(BBDD!$U:$U,BBDD!$C:$C,Summary!I$21,BBDD!$B:$B,Summary!$AJ$3) -> 0.12529101 | J31: =(J$22/IF($D$2="Chat",3,1)*J$23)/SUMIFS(BBDD!$U:$U,BBDD!$B:$B,Summary!$AJ$3) -> 0.39038249

Sheet Intraday
D2: Seleccione Canal | G2: Seleccione Día
AH3: Chat | AI3: 2 | AJ3: =IF(AI3=1,AH3,IF(AI3=2,AH4,"")) -> Voz | AM3: Lunes | AN3: 1 | AO3: =IF(AN3=1,AM3,IF(AN3=2,AM4,IF(AN3=3,AM5,IF(AN3=4,AM6,IF(AN3=5,AM7,IF(AN3=6,AM8,IF(AN3=7,AM9,0))))))) -> Lunes
AH4: Voz | AM4: Martes
AM5: Miércoles
AM6: Jueves
AM7: Viernes
AM8: Sábado
AM9: Domingo
B37: Intervalos | C37: Llamadas Pronosticadas | D37: TMO (seg.) | E37: Asesores Requeridos | F37: Ases. Req con Reductores | G37: % Reductor | H37: Asesores Programados | I37: Diferencia | J37: % Nivel Serv. Esperado | K37: % Nivel Atención | L37: % Ocupación
C38: =SUM(C39:C70) -> 376 | D38: =SUMPRODUCT(D39:D70,C39:C70)/C38 -> 660 | E38: =SUM(E39:E70)/15 -> 15.8 | F38: =SUM(F39:F70)/15 -> 18.8 | G38: =SUMPRODUCT(G39:G70,C39:C70)/C38 -> 0.1 | H38: =SUM(H39:H70)/15 -> 21.733333 | I38: =SUM(I39:I70)/15 -> 2.9333333 | J38: =SUMPRODUCT(J39:J70,C39:C70)/C38 -> 0.90389119 | K38: =SUMPRODUCT(K39:K70,C39:C70)/C38 -> 1 | L38: =(C$38/IF($AJ$3="Chat",3,1)*D$38)/SUMIFS(BBDD!$U:$U,BBDD!$B:$B,Intraday!AJ$3,BBDD!$C:$C,Intraday!$AO$3) -> 0.42290389
B39: 0.25 | C39: =SUMIFS(BBDD!$E:$E,BBDD!$D:$D,Intraday!$B39,BBDD!$B:$B,Intraday!$AJ$3,BBDD!$C:$C,Intraday!$AO$3) -> 0 | D39: =SUMIFS(BBDD!$F:$F,BBDD!$D:$D,Intraday!$B39,BBDD!$B:$B,Intraday!$AJ$3,BBDD!$C:$C,Intraday!$AO$3) -> 0 | E39: =SUMIFS(BBDD!$J:$J,BBDD!$D:$D,Intraday!$B39,BBDD!$B:$B,Intraday!$AJ$3,BBDD!$C:$C,Intraday!$AO$3) -> 1 | F39: =SUMIFS(BBDD!$L:$L,BBDD!$D:$D,Intraday!$B39,BBDD!$B:$B,Intraday!$AJ$3,BBDD!$C:$C,Intraday!$AO$3) -> 2 | G39: 0.1 | H39: =SUMIFS(BBDD!$M:$M,BBDD!$D:$D,Intraday!$B39,BBDD!$B:$B,Intraday!$AJ$3,BBDD!$C:$C,Intraday!$AO$3) -> 2 | I39: =+H39-F39 -> 0 | J39: =SUMIFS(BBDD!$O:$O,BBDD!$D:$D,Intraday!$B39,BBDD!$B:$B,Intraday!$AJ$3,BBDD!$C:$C,Intraday!$AO$3) -> 0 | K39: =SUMIFS(BBDD!$P:$P,BBDD!$D:$D,Intraday!$B39,BBDD!$B:$B,Intraday!$AJ$3,BBDD!$C:$C,Intraday!$AO$3) -> 0 | L39: =($C39/IF($D$2="Chat",3,1)*$D39)/SUMIFS(BBDD!$U:$U,BBDD!$D:$D,Intraday!$B39,BBDD!$B:$B,Intraday!$AJ$3,BBDD!$C:$C,Intraday!$AO$3) -> 0
B40: 0.27083333 | C40: =SUMIFS(BBDD!$E:$E,BBDD!$D:$D,Intraday!$B40,BBDD!$B:$B,Intraday!$AJ$3,BBDD!$C:$C,Intraday!$AO$3) -> 3 | D40: =SUMIFS(BBDD!$F:$F,BBDD!$D:$D,Intraday!$B40,BBDD!$B:$B,Intraday!$AJ$3,BBDD!$C:$C,Intraday!$AO$3) -> 660 | E40: =SUMIFS(BBDD!$J:$J,BBDD!$D:$D,Intraday!$B40,BBDD!$B:$B,Intraday!$AJ$3,BBDD!$C:$C,Intraday!$AO$3) -> 3 | F40: =SUMIFS(BBDD!$L:$L,BBDD!$D:$D,Intraday!$B40,BBDD!$B:$B,Intraday!$AJ$3,BBDD!$C:$C,Intraday!$AO$3) -> 4 | G40: 0.1 | H40: =SUMIFS(BBDD!$M:$M,BBDD!$D:$D,Intraday!$B40,BBDD!$B:$B,Intraday!$AJ$3,BBDD!$C:$C,Intraday!$AO$3) -> 2 | I40: =+H40-F40 -> -2 | J40: =SUMIFS(BBDD!$O:$O,BBDD!$D:$D,Intraday!$B40,BBDD!$B:$B,Intraday!$AJ$3,BBDD!$C:$C,Intraday!$AO$3) -> 0.27670059 | K40: =SUMIFS(BBDD!$P:$P,BBDD!$D:$D,Intraday!$B40,BBDD!$B:$B,Intraday!$AJ$3,BBDD!$C:$C,Intraday!$AO$3) -> 1 | L40: =($C40/IF($D$2="Chat",3,1)*$D40)/SUMIFS(BBDD!$U:$U,BBDD!$D:$D,Intraday!$B40,BBDD!$B:$B,Intraday!$AJ$3,BBDD!$C:$C,Intraday!$AO$3) -> 0.55
B41: 0.29166667 | C41: =SUMIFS(BBDD!$E:$E,BBDD!$D:$D,Intraday!$B41,BBDD!$B:$B,Intraday!$AJ$3,BBDD!$C:$C,Intraday!$AO$3) -> 4 | D41: =SUMIFS(BBDD!$F:$F,BBDD!$D:$D,Intraday!$B41,BBDD!$B:$B,Intraday!$AJ$3,BBDD!$C:$C,Intraday!$AO$3) -> 660 | E41: =SUMIFS(BBDD!$J:$J,BBDD!$D:$D,Intraday!$B41,BBDD!$B:$B,Intraday!$AJ$3,BBDD!$C:$C,Intraday!$AO$3) -> 4 | F41: =SUMIFS(BBDD!$L:$L,BBDD!$D:$D,Intraday!$B41,BBDD!$B:$B,Intraday!$AJ$3,BBDD!$C:$C,Intraday!$AO$3) -> 5 | G41: 0.1 | H41: =SUMIFS(BBDD!$M:$M,BBDD!$D:$D,Intraday!$B41,BBDD!$B:$B,Intraday!$AJ$3,BBDD!$C:$C,Intraday!$AO$3) -> 5 | I41: =+H41-F41 -> 0 | J41: =SUMIFS(BBDD!$O:$O,BBDD!$D:$D,Intraday!$B41,BBDD!$B:$B,Intraday!$AJ$3,BBDD!$C:$C,Intraday!$AO$3) -> 0.94007736 | K41: =SUMIFS(BBDD!$P:$P,BBDD!$D:$D,Intraday!$B41,BBDD!$B:$B,Intraday!$AJ$3,BBDD!$C:$C,Intraday!$AO$3) -> 1 | L41: =($C41/IF($D$2="Chat",3,1)*$D41)/SUMIFS(BBDD!$U:$U,BBDD!$D:$D,Intraday!$B41,BBDD!$B:$B,Intraday!$AJ$3,BBDD!$C:$C,Intraday!$AO$3) -> 0.29333333
B42: 0.3125 | C42: =SUMIFS(BBDD!$E:$E,BBDD!$D:$D,Intraday!$B42,BBDD!$B:$B,Intraday!$AJ$3,BBDD!$C:$C,Intraday!$AO$3) -> 6 | D42: =SUMIFS(BBDD!$F:$F,BBDD!$D:$D,Intraday!$B42,BBDD!$B:$B,Intraday!$AJ$3,BBDD!$C:$C,Intraday!$AO$3) -> 660 | E42: =SUMIFS(BBDD!$J:$J,BBDD!$D:$D,Intraday!$B42,BBDD!$B:$B,Intraday!$AJ$3,BBDD!$C:$C,Intraday!$AO$3) -> 5 | F42: =SUMIFS(BBDD!$L:$L,BBDD!$D:$D,Intraday!$B42,BBDD!$B:$B,Intraday!$AJ$3,BBDD!$C:$C,Intraday!$AO$3) -> 6 | G42: 0.1 | H42: =SUMIFS(BBDD!$M:$M,BBDD!$D:$D,Intraday!$B42,BBDD!$B:$B,Intraday!$AJ$3,BBDD!$C:$C,Intraday!$AO$3) -> 5 | I42: =+H42-F42 -> -1 | J42: =SUMIFS(BBDD!$O:$O,BBDD!$D:$D,Intraday!$B42,BBDD!$B:$B,Intraday!$AJ$3,BBDD!$C:$C,Intraday!$AO$3) -> 0.80857062 | K42: =SUMIFS(BBDD!$P:$P,BBDD!$D:$D,Intraday!$B42,BBDD!$B:$B,Intraday!$AJ$3,BBDD!$C:$C,Intraday!$AO$3) -> 1 | L42: =($C42/IF($D$2="Chat",3,1)*$D42)/SUMIFS(BBDD!$U:$U,BBDD!$D:$D,Intraday!$B42,BBDD!$B:$B,Intraday!$AJ$3,BBDD!$C:$C,Intraday!$AO$3) -> 0.44
B43: 0.33333333 | C43: =SUMIFS(BBDD!$E:$E,BBDD!$D:$D,Intraday!$B43,BBDD!$B:$B,Intraday!$AJ$3,BBDD!$C:$C,Intraday!$AO$3) -> 20 | D43: =SUMIFS(BBDD!$F:$F,BBDD!$D:$D,Intraday!$B43,BBDD!$B:$B,Intraday!$AJ$3,BBDD!$C:$C,Intraday!$AO$3) -> 660 | E43: =SUMIFS(BBDD!$J:$J,BBDD!$D:$D,Intraday!$B43,BBDD!$B:$B,Intraday!$AJ$3,BBDD!$C:$C,Intraday!$AO$3) -> 11 | F43: =SUMIFS(BBDD!$L:$L,BBDD!$D:$D,Intraday!$B43,BBDD!$B:$B,Intraday!$AJ$3,BBDD!$C:$C,Intraday!$AO$3) -> 13 | G43: 0.1 | H43: =SUMIFS(BBDD!$M:$M,BBDD!$D:$D,Intraday!$B43,BBDD!$B:$B,Intraday!$AJ$3,BBDD!$C:$C,Intraday!$AO$3) -> 13 | I43: =+H43-F43 -> 0 | J43: =SUMIFS(BBDD!$O:$O,BBDD!$D:$D,Intraday!$B43,BBDD!$B:$B,Intraday!$AJ$3,BBDD!$C:$C,Intraday!$AO$3) -> 0.87584674 | K43: =SUMIFS(BBDD!$P:$P,BBDD!$D:$D,Intraday!$B43,BBDD!$B:$B,Intraday!$AJ$3,BBDD!$C:$C,Intraday!$AO$3) -> 1 | L43: =($C43/IF($D$2="Chat",3,1)*$D43)/SUMIFS(BBDD!$U:$U,BBDD!$D:$D,Intraday!$B43,BBDD!$B:$B,Intraday!$AJ$3,BBDD!$C:$C,Intraday!$AO$3) -> 0.56410256
B44: 0.35416667 | C44: =SUMIFS(BBDD!$E:$E,BBDD!$D:$D,Intraday!$B44,BBDD!$B:$B,Intraday!$AJ$3,BBDD!$C:$C,Intraday!$AO$3) -> 18 | D44: =SUMIFS(BBDD!$F:$F,BBDD!$D:$D,Intraday!$B44,BBDD!$B:$B,Intraday!$AJ$3,BBDD!$C:$C,Intraday!$AO$3) -> 660 | E44: =SUMIFS(BBDD!$J:$J,BBDD!$D:$D,Intraday!$B44,BBDD!$B:$B,Intraday!$AJ$3,BBDD!$C:$C,Intraday!$AO$3) -> 10 | F44: =SUMIFS(BBDD!$L:$L,BBDD!$D:$D,Intraday!$B44,BBDD!$B:$B,Intraday!$AJ$3,BBDD!$C:$C,Intraday!$AO$3) -> 12 | G44: 0.1 | H44: =SUMIFS(BBDD!$M:$M,BBDD!$D:$D,Intraday!$B44,BBDD!$B:$B,Intraday!$AJ$3,BBDD!$C:$C,Intraday!$AO$3) -> 13.5 | I44: =+H44-F44 -> 1.5 | J44: =SUMIFS(BBDD!$O:$O,BBDD!$D:$D,Intraday!$B44,BBDD!$B:$B,Intraday!$AJ$3,BBDD!$C:$C,Intraday!$AO$3) -> 0.96428555 | K44: =SUMIFS(BBDD!$P:$P,BBDD!$D:$D,Intraday!$B44,BBDD!$B:$B,Intraday!$AJ$3,BBDD!$C:$C,Intraday!$AO$3) -> 1 | L44: =($C44/IF($D$2="Chat",3,1)*$D44)/SUMIFS(BBDD!$U:$U,BBDD!$D:$D,Intraday!$B44,BBDD!$B:$B,Intraday!$AJ$3,BBDD!$C:$C,Intraday!$AO$3) -> 0.48888889
B45: 0.375 | C45: =SUMIFS(BBDD!$E:$E,BBDD!$D:$D,Intraday!$B45,BBDD!$B:$B,Intraday!$AJ$3,BBDD!$C:$C,Intraday!$AO$3) -> 17 | D45: =SUMIFS(BBDD!$F:$F,BBDD!$D:$D,Intraday!$B45,BBDD!$B:$B,Intraday!$AJ$3,BBDD!$C:$C,Intraday!$AO$3) -> 660 | E45: =SUMIFS(BBDD!$J:$J,BBDD!$D:$D,Intraday!$B45,BBDD!$B:$B,Intraday!$AJ$3,BBDD!$C:$C,Intraday!$AO$3) -> 10 | F45: =SUMIFS(BBDD!$L:$L,BBDD!$D:$D,Intraday!$B45,BBDD!$B:$B,Intraday!$AJ$3,BBDD!$C:$C,Intraday!$AO$3) -> 12 | G45: 0.1 | H45: =SUMIFS(BBDD!$M:$M,BBDD!$D:$D,Intraday!$B45,BBDD!$B:$B,Intraday!$AJ$3,BBDD!$C:$C,Intraday!$AO$3) -> 15.5 | I45: =+H45-F45 -> 3.5 | J45: =SUMIFS(BBDD!$O:$O,BBDD!$D:$D,Intraday!$B45,BBDD!$B:$B,Intraday!$AJ$3,BBDD!$C:$C,Intraday!$AO$3) -> 0.99033105 | K45: =SUMIFS(BBDD!$P:$P,BBDD!$D:$D,Intraday!$B45,BBDD!$B:$B,Intraday!$AJ$3,BBDD!$C:$C,Intraday!$AO$3) -> 1 | L45: =($C45/IF($D$2="Chat",3,1)*$D45)/SUMIFS(BBDD!$U:$U,BBDD!$D:$D,Intraday!$B45,BBDD!$B:$B,Intraday!$AJ$3,BBDD!$C:$C,Intraday!$AO$3) -> 0.40215054
B46: 0.39583333 | C46: =SUMIFS(BBDD!$E:$E,BBDD!$D:$D,Intraday!$B46,BBDD!$B:$B,Intraday!$AJ$3,BBDD!$C:$C,Intraday!$AO$3) -> 22 | D46: =SUMIFS(BBDD!$F:$F,BBDD!$D:$D,Intraday!$B46,BBDD!$B:$B,Intraday!$AJ$3,BBDD!$C:$C,Intraday!$AO$3) -> 660 | E46: =SUMIFS(BBDD!$J:$J,BBDD!$D:$D,Intraday!$B46,BBDD!$B:$B,Intraday!$AJ$3,BBDD!$C:$C,Intraday!$AO$3) -> 12 | F46: =SUMIFS(BBDD!$L:$L,BBDD!$D:$D,Intraday!$B46,BBDD!$B:$B,Intraday!$AJ$3,BBDD!$C:$C,Intraday!$AO$3) -> 14 | G46: 0.1 | H46: =SUMIFS(BBDD!$M:$M,BBDD!$D:$D,Intraday!$B46,BBDD!$B:$B,Intraday!$AJ$3,BBDD!$C:$C,Intraday!$AO$3) -> 14.5 | I46: =+H46-F46 -> 0.5 | J46: =SUMIFS(BBDD!$O:$O,BBDD!$D:$D,Intraday!$B46,BBDD!$B:$B,Intraday!$AJ$3,BBDD!$C:$C,Intraday!$AO$3) -> 0.93145025 | K46: =SUMIFS(BBDD!$P:$P,BBDD!$D:$D,Intraday!$B46,BBDD!$B:$B,Intraday!$AJ$3,BBDD!$C:$C,Intraday!$AO$3) -> 1 | L46: =($C46/IF($D$2="Chat",3,1)*$D46)/SUMIFS(BBDD!$U:$U,BBDD!$D:$D,Intraday!$B46,BBDD!$B:$B,Intraday!$AJ$3,BBDD!$C:$C,Intraday!$AO$3) -> 0.55632184
B47: 0.41666667 | C47: =SUMIFS(BBDD!$E:$E,BBDD!$D:$D,Intraday!$B47,BBDD!$B:$B,Intraday!$AJ$3,BBDD!$C:$C,Intraday!$AO$3) -> 24 | D47: =SUMIFS(BBDD!$F:$F,BBDD!$D:$D,Intraday!$B47,BBDD!$B:$B,Intraday!$AJ$3,BBDD!$C:$C,Intraday!$AO$3) -> 660 | E47: =SUMIFS(BBDD!$J:$J,BBDD!$D:$D,Intraday!$B47,BBDD!$B:$B,Intraday!$AJ$3,BBDD!$C:$C,Intraday!$AO$3) -> 13 | F47: =SUMIFS(BBDD!$L:$L,BBDD!$D:$D,Intraday!$B47,BBDD!$B:$B,Intraday!$AJ$3,BBDD!$C:$C,Intraday!$AO$3) -> 15 | G47: 0.1 | H47: =SUMIFS(BBDD!$M:$M,BBDD!$D:$D,Intraday!$B47,BBDD!$B:$B,Intraday!$AJ$3,BBDD!$C:$C,Intraday!$AO$3) -> 18.5 | I47: =+H47-F47 -> 3.5 | J47: =SUMIFS(BBDD!$O:$O,BBDD!$D:$D,Intraday!$B47,BBDD!$B:$B,Intraday!$AJ$3,BBDD!$C:$C,Intraday!$AO$3) -> 0.98444194 | K47: =SUMIFS(BBDD!$P:$P,BBDD!$D:$D,Intraday!$B47,BBDD!$B:$B,Intraday!$AJ$3,BBDD!$C:$C,Intraday!$AO$3) -> 1 | L47: =($C47/IF($D$2="Chat",3,1)*$D47)/SUMIFS(BBDD!$U:$U,BBDD!$D:$D,Intraday!$B47,BBDD!$B:$B,Intraday!$AJ$3,BBDD!$C:$C,Intraday!$AO$3) -> 0.47567568
B48: 0.4375 | C48: =SUMIFS(BBDD!$E:$E,BBDD!$D:$D,Intraday!$B48,BBDD!$B:$B,Intraday!$AJ$3,BBDD!$C:$C,Intraday!$AO$3) -> 20 | D48: =SUMIFS(BBDD!$F:$F,BBDD!$D:$D,Intraday!$B48,BBDD!$B:$B,Intraday!$AJ$3,BBDD!$C:$C,Intraday!$AO$3) -> 660 | E48: =SUMIFS(BBDD!$J:$J,BBDD!$D:$D,Intraday!$B48,BBDD!$B:$B,Intraday!$AJ$3,BBDD!$C:$C,Intraday!$AO$3) -> 11 | F48: =SUMIFS(BBDD!$L:$L,BBDD!$D:$D,Intraday!$B48,BBDD!$B:$B,Intraday!$AJ$3,BBDD!$C:$C,Intraday!$AO$3) -> 13 | G48: 0.1 | H48: =SUMIFS(BBDD!$M:$M,BBDD!$D:$D,Intraday!$B48,BBDD!$B:$B,Intraday!$AJ$3,BBDD!$C:$C,Intraday!$AO$3) -> 16.5 | I48: =+H48-F48 -> 3.5 | J48: =SUMIFS(BBDD!$O:$O,BBDD!$D:$D,Intraday!$B48,BBDD!$B:$B,Intraday!$AJ$3,BBDD!$C:$C,Intraday!$AO$3) -> 0.98467755 | K48: =SUMIFS(BBDD!$P:$P,BBDD!$D:$D,Intraday!$B48,BBDD!$B:$B,Intraday!$AJ$3,BBDD!$C:$C,Intraday!$AO$3) -> 1 | L48: =($C48/IF($D$2="Chat",3,1)*$D48)/SUMIFS(BBDD!$U:$U,BBDD!$D:$D,Intraday!$B48,BBDD!$B:$B,Intraday!$AJ$3,BBDD!$C:$C,Intraday!$AO$3) -> 0.44444444
B49: 0.45833333 | C49: =SUMIFS(BBDD!$E:$E,BBDD!$D:$D,Intraday!$B49,BBDD!$B:$B,Intraday!$AJ$3,BBDD!$C:$C,Intraday!$AO$3) -> 16 | D49: =SUMIFS(BBDD!$F:$F,BBDD!$D:$D,Intraday!$B49,BBDD!$B:$B,Intraday!$AJ$3,BBDD!$C:$C,Intraday!$AO$3) -> 660 | E49: =SUMIFS(BBDD!$J:$J,BBDD!$D:$D,Intraday!$B49,BBDD!$B:$B,Intraday!$AJ$3,BBDD!$C:$C,Intraday!$AO$3) -> 10 | F49: =SUMIFS(BBDD!$L:$L,BBDD!$D:$D,Intraday!$B49,BBDD!$B:$B,Intraday!$AJ$3,BBDD!$C:$C,Intraday!$AO$3) -> 12 | G49: 0.1 | H49: =SUMIFS(BBDD!$M:$M,BBDD!$D:$D,Intraday!$B49,BBDD!$B:$B,Intraday!$AJ$3,BBDD!$C:$C,Intraday!$AO$3) -> 18 | I49: =+H49-F49 -> 6 | J49: =SUMIFS(BBDD!$O:$O,BBDD!$D:$D,Intraday!$B49,BBDD!$B:$B,Intraday!$AJ$3,BBDD!$C:$C,Intraday!$AO$3) -> 0.99969447 | K49: =SUMIFS(BBDD!$P:$P,BBDD!$D:$D,Intraday!$B49,BBDD!$B:$B,Intraday!$AJ$3,BBDD!$C:$C,Intraday!$AO$3) -> 1 | L49: =($C49/IF($D$2="Chat",3,1)*$D49)/SUMIFS(BBDD!$U:$U,BBDD!$D:$D,Intraday!$B49,BBDD!$B:$B,Intraday!$AJ$3,BBDD!$C:$C,Intraday!$AO$3) -> 0.32592593
B50: 0.47916667 | C50: =SUMIFS(BBDD!$E:$E,BBDD!$D:$D,Intraday!$B50,BBDD!$B:$B,Intraday!$AJ$3,BBDD!$C:$C,Intraday!$AO$3) -> 19 | D50: =SUMIFS(BBDD!$F:$F,BBDD!$D:$D,Intraday!$B50,BBDD!$B:$B,Intraday!$AJ$3,BBDD!$C:$C,Intraday!$AO$3) -> 660 | E50: =SUMIFS(BBDD!$J:$J,BBDD!$D:$D,Intraday!$B50,BBDD!$B:$B,Intraday!$AJ$3,BBDD!$C:$C,Intraday!$AO$3) -> 11 | F50: =SUMIFS(BBDD!$L:$L,BBDD!$D:$D,Intraday!$B50,BBDD!$B:$B,Intraday!$AJ$3,BBDD!$C:$C,Intraday!$AO$3) -> 13 | G50: 0.1 | H50: =SUMIFS(BBDD!$M:$M,BBDD!$D:$D,Intraday!$B50,BBDD!$B:$B,Intraday!$AJ$3,BBDD!$C:$C,Intraday!$AO$3) -> 18 | I50: =+H50-F50 -> 5 | J50: =SUMIFS(BBDD!$O:$O,BBDD!$D:$D,Intraday!$B50,BBDD!$B:$B,Intraday!$AJ$3,BBDD!$C:$C,Intraday!$AO$3) -> 0.99816018 | K50: =SUMIFS(BBDD!$P:$P,BBDD!$D:$D,Intraday!$B50,BBDD!$B:$B,Intraday!$AJ$3,BBDD!$C:$C,Intraday!$AO$3) -> 1 | L50: =($C50/IF($D$2="Chat",3,1)*$D50)/SUMIFS(BBDD!$U:$U,BBDD!$D:$D,Intraday!$B50,BBDD!$B:$B,Intraday!$AJ$3,BBDD!$C:$C,Intraday!$AO$3) -> 0.38703704
... B70: 0.89583333 | C70: =SUMIFS(BBDD!$E:$E,BBDD!$D:$D,Intraday!$B70,BBDD!$B:$B,Intraday!$AJ$3,BBDD!$C:$C,Intraday!$AO$3) -> 1 | D70: =SUMIFS(BBDD!$F:$F,BBDD!$D:$D,Intraday!$B70,BBDD!$B:$B,Intraday!$AJ$3,BBDD!$C:$C,Intraday!$AO$3) -> 660 | E70: =SUMIFS(BBDD!$J:$J,BBDD!$D:$D,Intraday!$B70,BBDD!$B:$B,Intraday!$AJ$3,BBDD!$C:$C,Intraday!$AO$3) -> 2 | F70: =SUMIFS(BBDD!$L:$L,BBDD!$D:$D,Intraday!$B70,BBDD!$B:$B,Intraday!$AJ$3,BBDD!$C:$C,Intraday!$AO$3) -> 3 | G70: 0.1 | H70: =SUMIFS(BBDD!$M:$M,BBDD!$D:$D,Intraday!$B70,BBDD!$B:$B,Intraday!$AJ$3,BBDD!$C:$C,Intraday!$AO$3) -> 2 | I70: =+H70-F70 -> -1 | J70: =SUMIFS(BBDD!$O:$O,BBDD!$D:$D,Intraday!$B70,BBDD!$B:$B,Intraday!$AJ$3,BBDD!$C:$C,Intraday!$AO$3) -> 0.69811451 | K70: =SUMIFS(BBDD!$P:$P,BBDD!$D:$D,Intraday!$B70,BBDD!$B:$B,Intraday!$AJ$3,BBDD!$C:$C,Intraday!$AO$3) -> 1 | L70: =($C70/IF($D$2="Chat",3,1)*$D70)/SUMIFS(BBDD!$U:$U,BBDD!$D:$D,Intraday!$B70,BBDD!$B:$B,Intraday!$AJ$3,BBDD!$C:$C,Intraday!$AO$3) -> 0.18333333

Sheet Schedule
E2: Dia Think
B5: Nombre | C5: Total Horas | D5: Canal | E5: Lunes | M5: Martes | U5: Miercoles | AC5: Jueves | AK5: Viernes | AS5: Sábado | BA5: Domingo
E6: SHIFT | G6: BREAK 1 | I6: BREAK 2 | K6: LUNCH | M6: SHIFT | O6: BREAK 1 | Q6: BREAK 2 | S6: LUNCH | U6: SHIFT | W6: BREAK 1 | Y6: BREAK 2 | AA6: LUNCH | AC6: SHIFT | AE6: BREAK 1 | AG6: BREAK 2 | AI6: LUNCH | AK6: SHIFT | AM6: BREAK 1 | AO6: BREAK 2 | AQ6: LUNCH | AS6: SHIFT | AU6: BREAK 1 | AW6: BREAK 2 | AY6: LUNCH | BA6: SHIFT | BC6: BREAK 1 | BE6: BREAK 2 | BG6: LUNCH
E7: Start | F7: End | G7: Start | H7: End | I7: Start | J7: End | K7: Start | L7: End | M7: Start | N7: End | O7: Start | P7: End | Q7: Start | R7: End | S7: Start | T7: End | U7: Start | V7: End | W7: Start | X7: End | Y7: Start | Z7: End | AA7: Start | AB7: End | AC7: Start | AD7: End | AE7: Start | AF7: End | AG7: Start | AH7: End | AI7: Start | AJ7: End | AK7: Start | AL7: End | AM7: Start | AN7: End | AO7: Start | AP7: End | AQ7: Start | AR7: End | AS7: Start | AT7: End | AU7: Start | AV7: End | AW7: Start | AX7: End | AY7: Start | AZ7: End | BA7: Start | BB7: End | BC7: Start | BD7: End | BE7: Start | BF7: End | BG7: Start | BH7: End
B8: ISABELLA MARTINEZ POLOCHE | C8: =+(F8-E8-(L8-K8))+(N8-M8-(T8-S8))+(V8-U8-(AB8-AA8))+(AD8-AC8-(AJ8-AI8))+(AL8-AK8-(AR8-AQ8))+(AT8-AS8-(AZ8-AY8))+(BB8-BA8-(BH8-BG8)) -> 1.875 | D8: Voz | E8: 0.25 | F8: 0.5625 | G8: 0.34375 | H8: 0.35416667 | I8: 0.47916667 | J8: 0.48958333 | K8: 0 | L8: 0 | M8: 0.25 | N8: 0.58333333 | O8: 0.34375 | P8: 0.35416667 | Q8: 0.47916667 | R8: 0.48958333 | S8: 0 | T8: 0 | U8: 0.25 | V8: 0.5625 | W8: 0.34375 | X8: 0.35416667 | Y8: 0.47916667 | Z8: 0.48958333 | AA8: 0 | AB8: 0 | AC8: 0.25 | AD8: 0.5625 | AE8: 0.34375 | AF8: 0.35416667 | AG8: 0.47916667 | AH8: 0.48958333 | AI8: 0 | AJ8: 0 | AK8: 0.25 | AL8: 0.5625 | AM8: 0.34375 | AN8: 0.35416667 | AO8: 0.47916667 | AP8: 0.48958333 | AQ8: 0 | AR8: 0 | AS8: 0 | AT8: 0 | AU8: 0 | AV8: 0 | AW8: 0 | AX8: 0 | AY8: 0 | AZ8: 0 | BA8: 0.375 | BB8: 0.66666667 | BC8: 0.4375 | BD8: 0.44791667 | BE8: 0.54166667 | BF8: 0.55208333 | BG8: 0 | BH8: 0
B9: JAVIER MAURICIO QUINTERO OLIVEROS | C9: =+(F9-E9-(L9-K9))+(N9-M9-(T9-S9))+(V9-U9-(AB9-AA9))+(AD9-AC9-(AJ9-AI9))+(AL9-AK9-(AR9-AQ9))+(AT9-AS9-(AZ9-AY9))+(BB9-BA9-(BH9-BG9)) -> 1.875 | D9: Voz | E9: 0.25 | F9: 0.5625 | G9: 0.35416667 | H9: 0.36458333 | I9: 0.5 | J9: 0.51041667 | K9: 0 | L9: 0 | M9: 0.25 | N9: 0.5625 | O9: 0.35416667 | P9: 0.36458333 | Q9: 0.5 | R9: 0.51041667 | S9: 0 | T9: 0 | U9: 0.25 | V9: 0.5625 | W9: 0.35416667 | X9: 0.36458333 | Y9: 0.5 | Z9: 0.51041667 | AA9: 0 | AB9: 0 | AC9: 0.25 | AD9: 0.5625 | AE9: 0.35416667 | AF9: 0.36458333 | AG9: 0.5 | AH9: 0.51041667 | AI9: 0 | AJ9: 0 | AK9: 0.25 | AL9: 0.5625 | AM9: 0.35416667 | AN9: 0.36458333 | AO9: 0.5 | AP9: 0.51041667 | AQ9: 0 | AR9: 0 | AS9: 0.60416667 | AT9: 0.91666667 | AU9: 0.69791667 | AV9: 0.70833333 | AW9: 0.84375 | AX9: 0.85416667 | AY9: 0 | AZ9: 0 | BA9: 0 | BB9: 0 | BC9: 0 | BD9: 0 | BE9: 0 | BF9: 0 | BG9: 0 | BH9: 0
B10: WILSON ALBEIRO AVENDAÑO RODRIGUEZ | C10: =+(F10-E10-(L10-K10))+(N10-M10-(T10-S10))+(V10-U10-(AB10-AA10))+(AD10-AC10-(AJ10-AI10))+(AL10-AK10-(AR10-AQ10))+(AT10-AS10-(AZ10-AY10))+(BB10-BA10-(BH10-BG10)) -> 1.875 | D10: Voz | E10: 0.60416667 | F10: 0.91666667 | G10: 0.69791667 | H10: 0.70833333 | I10: 0.83333333 | J10: 0.84375 | K10: 0 | L10: 0 | M10: 0.58333333 | N10: 0.91666667 | O10: 0.67708333 | P10: 0.6875 | Q10: 0.8125 | R10: 0.82291667 | S10: 0 | T10: 0 | U10: 0.60416667 | V10: 0.91666667 | W10: 0.69791667 | X10: 0.70833333 | Y10: 0.83333333 | Z10: 0.84375 | AA10: 0 | AB10: 0 | AC10: 0.60416667 | AD10: 0.91666667 | AE10: 0.69791667 | AF10: 0.70833333 | AG10: 0.83333333 | AH10: 0.84375 | AI10: 0 | AJ10: 0 | AK10: 0.60416667 | AL10: 0.91666667 | AM10: 0.69791667 | AN10: 0.70833333 | AO10: 0.83333333 | AP10: 0.84375 | AQ10: 0 | AR10: 0 | AS10: 0 | AT10: 0 | AU10: 0 | AV10: 0 | AW10: 0 | AX10: 0 | AY10: 0 | AZ10: 0 | BA10: 0.375 | BB10: 0.66666667 | BC10: 0.52083333 | BD10: 0.53125 | BE10: 0.58333333 | BF10: 0.59375 | BG10: 0 | BH10: 0
B11: JUAN FRAANCISCO MONROY MONGUA | C11: =+(F11-E11-(L11-K11))+(N11-M11-(T11-S11))+(V11-U11-(AB11-AA11))+(AD11-AC11-(AJ11-AI11))+(AL11-AK11-(AR11-AQ11))+(AT11-AS11-(AZ11-AY11))+(BB11-BA11-(BH11-BG11)) -> 1.875 | D11: Voz | E11: 0.60416667 | F11: 0.91666667 | G11: 0.70833333 | H11: 0.71875 | I11: 0.85416667 | J11: 0.86458333 | K11: 0 | L11: 0 | M11: 0.60416667 | N11: 0.91666667 | O11: 0.70833333 | P11: 0.71875 | Q11: 0.85416667 | R11: 0.86458333 | S11: 0 | T11: 0 | U11: 0.60416667 | V11: 0.91666667 | W11: 0.70833333 | X11: 0.71875 | Y11: 0.85416667 | Z11: 0.86458333 | AA11: 0 | AB11: 0 | AC11: 0.60416667 | AD11: 0.91666667 | AE11: 0.70833333 | AF11: 0.71875 | AG11: 0.85416667 | AH11: 0.86458333 | AI11: 0 | AJ11: 0 | AK11: 0.625 | AL11: 0.91666667 | AM11: 0.72916667 | AN11: 0.73958333 | AO11: 0.875 | AP11: 0.88541667 | AQ11: 0 | AR11: 0 | AS11: 0.33333333 | AT11: 0.70833333 | AU11: 0.42708333 | AV11: 0.4375 | AW11: 0.65625 | AX11: 0.66666667 | AY11: 0.5 | AZ11: 0.54166667 | BA11: 0 | BB11: 0 | BC11: 0 | BD11: 0 | BE11: 0 | BF11: 0 | BG11: 0 | BH11: 0
B12: AVILA CAMACHO DAVID ANDRES | C12: =+(F12-E12-(L12-K12))+(N12-M12-(T12-S12))+(V12-U12-(AB12-AA12))+(AD12-AC12-(AJ12-AI12))+(AL12-AK12-(AR12-AQ12))+(AT12-AS12-(AZ12-AY12))+(BB12-BA12-(BH12-BG12)) -> 1.875 | D12: Voz | E12: 0.52083333 | F12: 0.83333333 | G12: 0.625 | H12: 0.63916667 | I12: 0.66666667 | J12: 0.68083333 | K12: 0 | L12: 0 | M12: 0.5 | N12: 0.83333333 | O12: 0.625 | P12: 0.63916667 | Q12: 0.66666667 | R12: 0.68083333 | S12: 0 | T12: 0 | U12: 0.52083333 | V12: 0.83333333 | W12: 0.625 | X12: 0.63916667 | Y12: 0.66666667 | Z12: 0.68083333 | AA12: 0 | AB12: 0 | AC12: 0.52083333 | AD12: 0.83333333 | AE12: 0.625 | AF12: 0.63916667 | AG12: 0.66666667 | AH12: 0.68083333 | AI12: 0 | AJ12: 0 | AK12: 0.52083333 | AL12: 0.83333333 | AM12: 0.625 | AN12: 0.63916667 | AO12: 0.66666667 | AP12: 0.68083333 | AQ12: 0 | AR12: 0 | AS12: 0.375 | AT12: 0.70833333 | AU12: 0.46875 | AV12: 0.48291667 | AW12: 0.64958333 | AX12: 0.66 | AY12: 0.54166667 | AZ12: 0.58333333 | BA12: 0 | BB12: 0 | BC12: 0 | BD12: 0 | BE12: 0 | BF12: 0 | BG12: 0 | BH12: 0
B13: SANDRA MILENA RUIZ | C13: =+(F13-E13-(L13-K13))+(N13-M13-(T13-S13))+(V13-U13-(AB13-AA13))+(AD13-AC13-(AJ13-AI13))+(AL13-AK13-(AR13-AQ13))+(AT13-AS13-(AZ13-AY13))+(BB13-BA13-(BH13-BG13)) -> 1.875 | D13: Voz | E13: 0.375 | F13: 0.75 | G13: 0.46875 | H13: 0.48291667 | I13: 0.64583333 | J13: 0.66 | K13: 0.52083333 | L13: 0.5625 | M13: 0.375 | N13: 0.75 | O13: 0.46875 | P13: 0.48291667 | Q13: 0.64583333 | R13: 0.66 | S13: 0.52083333 | T13: 0.5625 | U13: 0.375 | V13: 0.75 | W13: 0.46875 | X13: 0.48291667 | Y13: 0.64583333 | Z13: 0.66 | AA13: 0.52083333 | AB13: 0.5625 | AC13: 0.375 | AD13: 0.75 | AE13: 0.46875 | AF13: 0.48291667 | AG13: 0.64583333 | AH13: 0.66 | AI13: 0.52083333 | AJ13: 0.5625 | AK13: 0.375 | AL13: 0.75 | AM13: 0.46875 | AN13: 0.48291667 | AO13: 0.64583333 | AP13: 0.66 | AQ13: 0.52083333 | AR13: 0.5625 | AS13: 0 | AT13: 0 | AU13: 0 | AV13: 0 | AW13: 0 | AX13: 0 | AY13: 0 | AZ13: 0 | BA13: 0.33333333 | BB13: 0.54166667 | BC13: 0.47916667 | BD13: 0.49333333 | BE13: 0 | BF13: 0 | BG13: 0 | BH13: 0
B14: ANDRES FELIPE RINCON AGUDELO | C14: =+(F14-E14-(L14-K14))+(N14-M14-(T14-S14))+(V14-U14-(AB14-AA14))+(AD14-AC14-(AJ14-AI14))+(AL14-AK14-(AR14-AQ14))+(AT14-AS14-(AZ14-AY14))+(BB14-BA14-(BH14-BG14)) -> 1.875 | D14: Voz | E14: 0.35416667 | F14: 0.70833333 | G14: 0.45833333 | H14: 0.4725 | I14: 0.63541667 | J14: 0.64958333 | K14: 0.5 | L14: 0.54166667 | M14: 0.35416667 | N14: 0.70833333 | O14: 0.45833333 | P14: 0.4725 | Q14: 0.63541667 | R14: 0.64958333 | S14: 0.5 | T14: 0.54166667 | U14: 0.35416667 | V14: 0.70833333 | W14: 0.45833333 | X14: 0.4725 | Y14: 0.63541667 | Z14: 0.64958333 | AA14: 0.5 | AB14: 0.54166667 | AC14: 0.35416667 | AD14: 0.70833333 | AE14: 0.45833333 | AF14: 0.4725 | AG14: 0.63541667 | AH14: 0.64958333 | AI14: 0.5 | AJ14: 0.54166667 | AK14: 0.35416667 | AL14: 0.70833333 | AM14: 0.45833333 | AN14: 0.4725 | AO14: 0.63541667 | AP14: 0.64958333 | AQ14: 0.5 | AR14: 0.54166667 | AS14: 0.60416667 | AT14: 0.91666667 | AU14: 0.67708333 | AV14: 0.69125 | AW14: 0.82666667 | AX14: 0.83708333 | AY14: 0 | AZ14: 0 | BA14: 0 | BB14: 0 | BC14: 0 | BD14: 0 | BE14: 0 | BF14: 0 | BG14: 0 | BH14: 0
B15: JORGE EDUARDO RODRIGUEZ BUITRAGO | C15: =+(F15-E15-(L15-K15))+(N15-M15-(T15-S15))+(V15-U15-(AB15-AA15))+(AD15-AC15-(AJ15-AI15))+(AL15-AK15-(AR15-AQ15))+(AT15-AS15-(AZ15-AY15))+(BB15-BA15-(BH15-BG15)) -> 1.875 | D15: Voz | E15: 0.33333333 | F15: 0.70833333 | G15: 0.44791667 | H15: 0.46208333 | I15: 0.625 | J15: 0.63916667 | K15: 0.52083333 | L15: 0.5625 | M15: 0.33333333 | N15: 0.70833333 | O15: 0.44791667 | P15: 0.46208333 | Q15: 0.625 | R15: 0.63916667 | S15: 0.52083333 | T15: 0.5625 | U15: 0.33333333 | V15: 0.70833333 | W15: 0.44791667 | X15: 0.46208333 | Y15: 0.625 | Z15: 0.63916667 | AA15: 0.52083333 | AB15: 0.5625 | AC15: 0.33333333 | AD15: 0.70833333 | AE15: 0.44791667 | AF15: 0.46208333 | AG15: 0.625 | AH15: 0.63916667 | AI15: 0.52083333 | AJ15: 0.5625 | AK15: 0.33333333 | AL15: 0.70833333 | AM15: 0.44791667 | AN15: 0.46208333 | AO15: 0.625 | AP15: 0.63916667 | AQ15: 0.52083333 | AR15: 0.5625 | AS15: 0.33333333 | AT15: 0.54166667 | AU15: 0.42708333 | AV15: 0.44125 | AW15: 0 | AX15: 0 | AY15: 0 | AZ15: 0 | BA15: 0 | BB15: 0 | BC15: 0 | BD15: 0 | BE15: 0 | BF15: 0 | BG15: 0 | BH15: 0
B16: JOSE EDWIN RONCANCIO RIVERA | C16: =+(F16-E16-(L16-K16))+(N16-M16-(T16-S16))+(V16-U16-(AB16-AA16))+(AD16-AC16-(AJ16-AI16))+(AL16-AK16-(AR16-AQ16))+(AT16-AS16-(AZ16-AY16))+(BB16-BA16-(BH16-BG16)) -> 1.875 | D16: Voz | E16: 0.33333333 | F16: 0.70833333 | G16: 0.42708333 | H16: 0.44125 | I16: 0.60416667 | J16: 0.61833333 | K16: 0.52083333 | L16: 0.5625 | M16: 0.33333333 | N16: 0.70833333 | O16: 0.42708333 | P16: 0.44125 | Q16: 0.60416667 | R16: 0.61833333 | S16: 0.52083333 | T16: 0.5625 | U16: 0.33333333 | V16: 0.70833333 | W16: 0.42708333 | X16: 0.44125 | Y16: 0.60416667 | Z16: 0.61833333 | AA16: 0.52083333 | AB16: 0.5625 | AC16: 0.33333333 | AD16: 0.70833333 | AE16: 0.42708333 | AF16: 0.44125 | AG16: 0.60416667 | AH16: 0.61833333 | AI16: 0.52083333 | AJ16: 0.5625 | AK16: 0.33333333 | AL16: 0.70833333 | AM16: 0.42708333 | AN16: 0.44125 | AO16: 0.60416667 | AP16: 0.61833333 | AQ16: 0.52083333 | AR16: 0.5625 | AS16: 0.33333333 | AT16: 0.54166667 | AU16: 0.4375 | AV16: 0.45166667 | AW16: 0 | AX16: 0 | AY16: 0 | AZ16: 0 | BA16: 0 | BB16: 0 | BC16: 0 | BD16: 0 | BE16: 0 | BF16: 0 | BG16: 0 | BH16: 0
B17: JUAN CARLOS SEPULVEDA DAZA | C17: =+(F17-E17-(L17-K17))+(N17-M17-(T17-S17))+(V17-U17-(AB17-AA17))+(AD17-AC17-(AJ17-AI17))+(AL17-AK17-(AR17-AQ17))+(AT17-AS17-(AZ17-AY17))+(BB17-BA17-(BH17-BG17)) -> 1.875 | D17: Voz | E17: 0.29166667 | F17: 0.6875 | G17: 0.38541667 | H17: 0.39958333 | I17: 0.60416667 | J17: 0.61833333 | K17: 0.5 | L17: 0.54166667 | M17: 0.29166667 | N17: 0.6875 | O17: 0.38541667 | P17: 0.39958333 | Q17: 0.60416667 | R17: 0.61833333 | S17: 0.5 | T17: 0.54166667 | U17: 0.29166667 | V17: 0.66666667 | W17: 0.38541667 | X17: 0.39958333 | Y17: 0.60416667 | Z17: 0.61833333 | AA17: 0.5 | AB17: 0.54166667 | AC17: 0.29166667 | AD17: 0.66666667 | AE17: 0.38541667 | AF17: 0.39958333 | AG17: 0.60416667 | AH17: 0.61833333 | AI17: 0.5 | AJ17: 0.54166667 | AK17: 0.29166667 | AL17: 0.66666667 | AM17: 0.38541667 | AN17: 0.39958333 | AO17: 0.60416667 | AP17: 0.61833333 | AQ17: 0.5 | AR17: 0.54166667 | AS17: 0 | AT17: 0 | AU17: 0 | AV17: 0 | AW17: 0 | AX17: 0 | AY17: 0 | AZ17: 0 | BA17: 0.33333333 | BB17: 0.5 | BC17: 0.39583333 | BD17: 0.41 | BE17: 0 | BF17: 0 | BG17: 0 | BH17: 0
B18: MARÍA CAMILA TANGARIFE RAMIREZ | C18: =+(F18-E18-(L18-K18))+(N18-M18-(T18-S18))+(V18-U18-(AB18-AA18))+(AD18-AC18-(AJ18-AI18))+(AL18-AK18-(AR18-AQ18))+(AT18-AS18-(AZ18-AY18))+(BB18-BA18-(BH18-BG18)) -> 1.875 | D18: Voz | E18: 0.29166667 | F18: 0.66666667 | G18: 0.375 | H18: 0.38916667 | I18: 0.59375 | J18: 0.60791667 | K18: 0.5 | L18: 0.54166667 | M18: 0.29166667 | N18: 0.66666667 | O18: 0.375 | P18: 0.38916667 | Q18: 0.59375 | R18: 0.60791667 | S18: 0.5 | T18: 0.54166667 | U18: 0.29166667 | V18: 0.66666667 | W18: 0.375 | X18: 0.38916667 | Y18: 0.59375 | Z18: 0.60791667 | AA18: 0.5 | AB18: 0.54166667 | AC18: 0.29166667 | AD18: 0.66666667 | AE18: 0.375 | AF18: 0.38916667 | AG18: 0.59375 | AH18: 0.60791667 | AI18: 0.5 | AJ18: 0.54166667 | AK18: 0.29166667 | AL18: 0.66666667 | AM18: 0.375 | AN18: 0.38916667 | AO18: 0.59375 | AP18: 0.60791667 | AQ18: 0.5 | AR18: 0.54166667 | AS18: 0.375 | AT18: 0.58333333 | AU18: 0.46875 | AV18: 0.48291667 | AW18: 0 | AX18: 0 | AY18: 0 | AZ18: 0 | BA18: 0 | BB18: 0 | BC18: 0 | BD18: 0 | BE18: 0 | BF18: 0 | BG18: 0 | BH18: 0
B19: CAMILO ANDRÉS SILVA FLÓREZ | C19: =+(F19-E19-(L19-K19))+(N19-M19-(T19-S19))+(V19-U19-(AB19-AA19))+(AD19-AC19-(AJ19-AI19))+(AL19-AK19-(AR19-AQ19))+(AT19-AS19-(AZ19-AY19))+(BB19-BA19-(BH19-BG19)) -> 1.875 | D19: Voz | E19: 0.29166667 | F19: 0.66666667 | G19: 0.38541667 | H19: 0.39958333 | I19: 0.60416667 | J19: 0.61833333 | K19: 0.5 | L19: 0.54166667 | M19: 0.29166667 | N19: 0.66666667 | O19: 0.38541667 | P19: 0.39958333 | Q19: 0.60416667 | R19: 0.61833333 | S19: 0.5 | T19: 0.54166667 | U19: 0.29166667 | V19: 0.66666667 | W19: 0.38541667 | X19: 0.39958333 | Y19: 0.60416667 | Z19: 0.61833333 | AA19: 0.5 | AB19: 0.54166667 | AC19: 0.29166667 | AD19: 0.66666667 | AE19: 0.38541667 | AF19: 0.39958333 | AG19: 0.60416667 | AH19: 0.61833333 | AI19: 0.5 | AJ19: 0.54166667 | AK19: 0.29166667 | AL19: 0.66666667 | AM19: 0.38541667 | AN19: 0.39958333 | AO19: 0.60416667 | AP19: 0.61833333 | AQ19: 0.5 | AR19: 0.54166667 | AS19: 0.29166667 | AT19: 0.5 | AU19: 0.38541667 | AV19: 0.39958333 | AW19: 0 | AX19: 0 | AY19: 0 | AZ19: 0 | BA19: 0 | BB19: 0 | BC19: 0 | BD19: 0 | BE19: 0 | BF19: 0 | BG19: 0 | BH19: 0
... B29: DAYANA STEFANI PINEDA MOYANO | C29: =+(F29-E29-(L29-K29))+(N29-M29-(T29-S29))+(V29-U29-(AB29-AA29))+(AD29-AC29-(AJ29-AI29))+(AL29-AK29-(AR29-AQ29))+(AT29-AS29-(AZ29-AY29))+(BB29-BA29-(BH29-BG29)) -> 1.875 | D29: Voz | E29: 0.33333333 | F29: 0.70833333 | G29: 0.4375 | H29: 0.45166667 | I29: 0.61458333 | J29: 0.62875 | K29: 0.54166667 | L29: 0.58333333 | M29: 0.33333333 | N29: 0.70833333 | O29: 0.4375 | P29: 0.45166667 | Q29: 0.61458333 | R29: 0.62875 | S29: 0.54166667 | T29: 0.58333333 | U29: 0.33333333 | V29: 0.70833333 | W29: 0.4375 | X29: 0.45166667 | Y29: 0.61458333 | Z29: 0.62875 | AA29: 0.54166667 | AB29: 0.58333333 | AC29: 0.33333333 | AD29: 0.70833333 | AE29: 0.4375 | AF29: 0.45166667 | AG29: 0.61458333 | AH29: 0.62875 | AI29: 0.54166667 | AJ29: 0.58333333 | AK29: 0.33333333 | AL29: 0.70833333 | AM29: 0.4375 | AN29: 0.45166667 | AO29: 0.61458333 | AP29: 0.62875 | AQ29: 0.54166667 | AR29: 0.58333333 | AS29: 0.45833333 | AT29: 0.66666667 | AU29: 0.44791667 | AV29: 0.46208333 | AW29: 0 | AX29: 0 | AY29: 0 | AZ29: 0 | BA29: 0 | BB29: 0 | BC29: 0 | BD29: 0 | BE29: 0 | BF29: 0 | BG29: 0 | BH29: 0
B30: HASSLY JULIETH BONILLA CRUZ | C30: 1.875 | D30: Chat | E30: 0.25 | F30: 0.54166667 | G30: 0.35416667 | H30: 0.36458333 | I30: 0.48958333 | J30: 0.5 | K30: 0 | L30: 0 | M30: 0.25 | N30: 0.54166667 | O30: 0.35416667 | P30: 0.36458333 | Q30: 0.48958333 | R30: 0.5 | S30: 0 | T30: 0 | U30: 0.25 | V30: 0.58333333 | W30: 0.35416667 | X30: 0.36458333 | Y30: 0.5 | Z30: 0.51041667 | AA30: 0 | AB30: 0 | AC30: 0.25 | AD30: 0.58333333 | AE30: 0.35416667 | AF30: 0.36458333 | AG30: 0.5 | AH30: 0.51041667 | AI30: 0 | AJ30: 0 | AK30: 0.25 | AL30: 0.58333333 | AM30: 0.35416667 | AN30: 0.36458333 | AO30: 0.5 | AP30: 0.51041667 | AQ30: 0 | AR30: 0 | AS30: 0 | AT30: 0 | AU30: 0 | AV30: 0 | AW30: 0 | AX30: 0 | AY30: 0 | AZ30: 0 | BA30: 0.375 | BB30: 0.66666667 | BC30: 0.46875 | BD30: 0.47916667 | BE30: 0 | BF30: 0 | BG30: 0 | BH30: 0
B31: ANDRES CAMILO GARCIA GONZALEZ | C31: 1.875 | D31: Chat | E31: 0.25 | F31: 0.58333333 | G31: 0.39583333 | H31: 0.40625 | I31: 0.52083333 | J31: 0.53125 | K31: 0 | L31: 0 | M31: 0.25 | N31: 0.58333333 | O31: 0.39583333 | P31: 0.40625 | Q31: 0.52083333 | R31: 0.53125 | S31: 0 | T31: 0 | U31: 0.25 | V31: 0.54166667 | W31: 0.39583333 | X31: 0.40625 | Y31: 0.47916667 | Z31: 0.48958333 | AA31: 0 | AB31: 0 | AC31: 0.25 | AD31: 0.54166667 | AE31: 0.39583333 | AF31: 0.40625 | AG31: 0.47916667 | AH31: 0.48958333 | AI31: 0 | AJ31: 0 | AK31: 0.25 | AL31: 0.54166667 | AM31: 0.39583333 | AN31: 0.40625 | AO31: 0.47916667 | AP31: 0.48958333 | AQ31: 0 | AR31: 0 | AS31: 0.58333333 | AT31: 0.91666667 | AU31: 0.6875 | AV31: 0.69791667 | AW31: 0.85416667 | AX31: 0.86458333 | AY31: 0 | AZ31: 0 | BA31: 0 | BB31: 0 | BC31: 0 | BD31: 0 | BE31: 0 | BF31: 0 | BG31: 0 | BH31: 0
B32: WILSON FERNANDO ALVAREZ RAMIREZ | C32: 1.875 | D32: Chat | E32: 0.58333333 | F32: 0.91666667 | G32: 0.72916667 | H32: 0.73958333 | I32: 0.86458333 | J32: 0.875 | K32: 0 | L32: 0 | M32: 0.58333333 | N32: 0.91666667 | O32: 0.72916667 | P32: 0.73958333 | Q32: 0.86458333 | R32: 0.875 | S32: 0 | T32: 0 | U32: 0.625 | V32: 0.91666667 | W32: 0.72916667 | X32: 0.73958333 | Y32: 0.86458333 | Z32: 0.875 | AA32: 0 | AB32: 0 | AC32: 0.625 | AD32: 0.91666667 | AE32: 0.72916667 | AF32: 0.73958333 | AG32: 0.86458333 | AH32: 0.875 | AI32: 0 | AJ32: 0 | AK32: 0.625 | AL32: 0.91666667 | AM32: 0.72916667 | AN32: 0.73958333 | AO32: 0.86458333 | AP32: 0.875 | AQ32: 0 | AR32: 0 | AS32: 0.25 | AT32: 0.58333333 | AU32: 0.67708333 | AV32: 0.6875 | AW32: 0.76041667 | AX32: 0.77083333 | AY32: 0 | AZ32: 0 | BA32: 0 | BB32: 0 | BC32: 0 | BD32: 0 | BE32: 0 | BF32: 0 | BG32: 0 | BH32: 0
B33: FRANK SEBASTIAN LOPEZ BENAVIDES | C33: 1.875 | D33: Chat | E33: 0.58333333 | F33: 0.91666667 | G33: 0.77083333 | H33: 0.78125 | I33: 0.88541667 | J33: 0.89583333 | K33: 0 | L33: 0 | M33: 0.58333333 | N33: 0.91666667 | O33: 0.77083333 | P33: 0.78125 | Q33: 0.88541667 | R33: 0.89583333 | S33: 0 | T33: 0 | U33: 0.58333333 | V33: 0.91666667 | W33: 0.77083333 | X33: 0.78125 | Y33: 0.88541667 | Z33: 0.89583333 | AA33: 0 | AB33: 0 | AC33: 0.58333333 | AD33: 0.91666667 | AE33: 0.77083333 | AF33: 0.78125 | AG33: 0.88541667 | AH33: 0.89583333 | AI33: 0 | AJ33: 0 | AK33: 0.58333333 | AL33: 0.91666667 | AM33: 0.77083333 | AN33: 0.78125 | AO33: 0.88541667 | AP33: 0.89583333 | AQ33: 0 | AR33: 0 | AS33: 0 | AT33: 0 | AU33: 0 | AV33: 0 | AW33: 0 | AX33: 0 | AY33: 0 | AZ33: 0 | BA33: 0.33333333 | BB33: 0.54166667 | BC33: 0.42708333 | BD33: 0.4375 | BE33: 0 | BF33: 0 | BG33: 0 | BH33: 0
B34: EDISON SANTIAGO RODRIGUEZ FLOREZ | C34: 1.875 | D34: Chat | E34: 0.45833333 | F34: 0.83333333 | G34: 0.6875 | H34: 0.70138889 | I34: 0.75 | J34: 0.76416667 | K34: 0.5625 | L34: 0.60416667 | M34: 0.45833333 | N34: 0.83333333 | O34: 0.6875 | P34: 0.70166667 | Q34: 0.75 | R34: 0.76416667 | S34: 0.5625 | T34: 0.60416667 | U34: 0.5 | V34: 0.83333333 | W34: 0.6875 | X34: 0.70166667 | Y34: 0.75 | Z34: 0.76416667 | AA34: 0.5625 | AB34: 0.60416667 | AC34: 0.5 | AD34: 0.83333333 | AE34: 0.6875 | AF34: 0.70166667 | AG34: 0.75 | AH34: 0.76416667 | AI34: 0.54166667 | AJ34: 0.58333333 | AK34: 0.45833333 | AL34: 0.83333333 | AM34: 0.6875 | AN34: 0.70166667 | AO34: 0.75 | AP34: 0.76416667 | AQ34: 0.5625 | AR34: 0.60416667 | AS34: 0.29166667 | AT34: 0.58333333 | AU34: 0.375 | AV34: 0.389 | AW34: 0.45833333 | AX34: 0.47233333 | AY34: 0 | AZ34: 0 | BA34: 0 | BB34: 0 | BC34: 0 | BD34: 0 | BE34: 0 | BF34: 0 | BG34: 0 | BH34: 0
B35: DEISY YOHANA BUITRAGO ESPITIA | C35: 1.875 | D35: Chat | E35: 0.375 | F35: 0.75 | G35: 0.47916667 | H35: 0.49305556 | I35: 0.66666667 | J35: 0.68083333 | K35: 0.54166667 | L35: 0.58333333 | M35: 0.375 | N35: 0.75 | O35: 0.47916667 | P35: 0.49333333 | Q35: 0.66666667 | R35: 0.68083333 | S35: 0.54166667 | T35: 0.58333333 | U35: 0.375 | V35: 0.75 | W35: 0.47916667 | X35: 0.49333333 | Y35: 0.66666667 | Z35: 0.68083333 | AA35: 0.54166667 | AB35: 0.58333333 | AC35: 0.375 | AD35: 0.75 | AE35: 0.47916667 | AF35: 0.49333333 | AG35: 0.66666667 | AH35: 0.68083333 | AI35: 0.52083333 | AJ35: 0.5625 | AK35: 0.375 | AL35: 0.75 | AM35: 0.47916667 | AN35: 0.49333333 | AO35: 0.66666667 | AP35: 0.68083333 | AQ35: 0.54166667 | AR35: 0.58333333 | AS35: 0 | AT35: 0 | AU35: 0 | AV35: 0 | AW35: 0 | AX35: 0 | AY35: 0 | AZ35: 0 | BA35: 0.375 | BB35: 0.58333333 | BC35: 0.5 | BD35: 0.514 | BE35: 0 | BF35: 0 | BG35: 0 | BH35: 0
B36: CLAUDIA MARCELA BELTRAN ROZO | C36: 1.875 | D36: Chat | E36: 0.4375 | F36: 0.79166667 | G36: 0.5 | H36: 0.51388889 | I36: 0.71875 | J36: 0.73291667 | K36: 0.58333333 | L36: 0.625 | M36: 0.4375 | N36: 0.79166667 | O36: 0.5 | P36: 0.51416667 | Q36: 0.71875 | R36: 0.73291667 | S36: 0.58333333 | T36: 0.625 | U36: 0.41666667 | V36: 0.70833333 | W36: 0.5 | X36: 0.51416667 | Y36: 0.67708333 | Z36: 0.69125 | AA36: 0 | AB36: 0 | AC36: 0.41666667 | AD36: 0.79166667 | AE36: 0.5 | AF36: 0.51416667 | AG36: 0.71875 | AH36: 0.73291667 | AI36: 0.58333333 | AJ36: 0.625 | AK36: 0.41666667 | AL36: 0.70833333 | AM36: 0.5 | AN36: 0.51416667 | AO36: 0.67708333 | AP36: 0.69125 | AQ36: 0 | AR36: 0 | AS36: 0.33333333 | AT36: 0.70833333 | AU36: 0.41666667 | AV36: 0.43066667 | AW36: 0.63541667 | AX36: 0.64941667 | AY36: 0.5 | AZ36: 0.54166667 | BA36: 0 | BB36: 0 | BC36: 0 | BD36: 0 | BE36: 0 | BF36: 0 | BG36: 0 | BH36: 0
B37: ADRIANA SARMIENTO HIGUERA | C37: 1.875 | D37: Chat | E37: 0.33333333 | F37: 0.70833333 | G37: 0.4375 | H37: 0.45138889 | I37: 0.625 | J37: 0.63916667 | K37: 0.52083333 | L37: 0.5625 | M37: 0.33333333 | N37: 0.70833333 | O37: 0.4375 | P37: 0.45166667 | Q37: 0.625 | R37: 0.63916667 | S37: 0.52083333 | T37: 0.5625 | U37: 0.33333333 | V37: 0.70833333 | W37: 0.4375 | X37: 0.45166667 | Y37: 0.625 | Z37: 0.63916667 | AA37: 0.52083333 | AB37: 0.5625 | AC37: 0.33333333 | AD37: 0.70833333 | AE37: 0.4375 | AF37: 0.45166667 | AG37: 0.625 | AH37: 0.63916667 | AI37: 0.5 | AJ37: 0.54166667 | AK37: 0.25 | AL37: 0.58333333 | AM37: 0.35416667 | AN37: 0.36458333 | AO37: 0.5 | AP37: 0.51041667 | AQ37: 0 | AR37: 0 | AS37: 0.66666667 | AT37: 0.875 | AU37: 0.75 | AV37: 0.764 | AW37: 0 | AX37: 0 | AY37: 0 | AZ37: 0 | BA37: 0 | BB37: 0 | BC37: 0 | BD37: 0 | BE37: 0 | BF37: 0 | BG37: 0 | BH37: 0
B38: BERTHA JULIET SANDOVAL AMAYA | C38: 1.875 | D38: Chat | E38: 0.33333333 | F38: 0.70833333 | G38: 0.40972222 | H38: 0.41678241 | I38: 0.64583333 | J38: 0.66 | K38: 0.5 | L38: 0.54166667 | M38: 0.33333333 | N38: 0.625 | O38: 0.40636574 | P38: 0.42053241 | Q38: 0.64583333 | R38: 0.66 | S38: 0.5 | T38: 0.54166667 | U38: 0.33333333 | V38: 0.70833333 | W38: 0.40636574 | X38: 0.42053241 | Y38: 0.64583333 | Z38: 0.66 | AA38: 0.5 | AB38: 0.54166667 | AC38: 0.33333333 | AD38: 0.66666667 | AE38: 0.40636574 | AF38: 0.42053241 | AG38: 0.64583333 | AH38: 0.66 | AI38: 0 | AJ38: 0 | AK38: 0.33333333 | AL38: 0.70833333 | AM38: 0.40636574 | AN38: 0.42053241 | AO38: 0.64583333 | AP38: 0.66 | AQ38: 0.5 | AR38: 0.54166667 | AS38: 0.29166667 | AT38: 0.58333333 | AU38: 0.38541667 | AV38: 0.39941667 | AW38: 0.46875 | AX38: 0.48275 | AY38: 0 | AZ38: 0 | BA38: 0 | BB38: 0 | BC38: 0 | BD38: 0 | BE38: 0 | BF38: 0 | BG38: 0 | BH38: 0
B39: MERCY LILIANA CASTEBLANCO NOVOA | C39: 1.875 | D39: Chat | E39: 0.33333333 | F39: 0.70833333 | G39: 0.41666667 | H39: 0.43083333 | I39: 0.63541667 | J39: 0.64958333 | K39: 0.52083333 | L39: 0.5625 | M39: 0.33333333 | N39: 0.70833333 | O39: 0.41666667 | P39: 0.43083333 | Q39: 0.63541667 | R39: 0.64958333 | S39: 0.52083333 | T39: 0.5625 | U39: 0.33333333 | V39: 0.625 | W39: 0.41666667 | X39: 0.43083333 | Y39: 0.57291667 | Z39: 0.58708333 | AA39: 0 | AB39: 0 | AC39: 0.33333333 | AD39: 0.625 | AE39: 0.41666667 | AF39: 0.43083333 | AG39: 0.57291667 | AH39: 0.58708333 | AI39: 0 | AJ39: 0 | AK39: 0.33333333 | AL39: 0.625 | AM39: 0.41666667 | AN39: 0.43083333 | AO39: 0.57291667 | AP39: 0.58708333 | AQ39: 0 | AR39: 0 | AS39: 0.33333333 | AT39: 0.70833333 | AU39: 0.42708333 | AV39: 0.44108333 | AW39: 0.625 | AX39: 0.639 | AY39: 0.54166667 | AZ39: 0.58333333 | BA39: 0 | BB39: 0 | BC39: 0 | BD39: 0 | BE39: 0 | BF39: 0 | BG39: 0 | BH39: 0

Sheet BBDD
B3: Canal | C3: Dia | D3: Intervalo | E3: Pronóstico Llamadas | F3: TMO (seg.) | G3: U=Int. Tiempo/TMO | H3: Intensidad Tráfico (r) | I3: Prob Llam Cola (C(k,r)) | J3: Asesores Requeridos | K3: % Nivel Serv. Ideal | L3: Ases. Req con Reductores | M3: Asesores Programados | N3: Diferencia | O3: % Nivel Serv. Esperado | P3: % Nivel Atención | Q3: % Ocupación | R3: % Reductor
B4: Chat | C4: Lunes | D4: 0.25 | E4: 0 | F4: 0 | G4: 2 | H4: 0 | I4: #NAME? | J4: 1 | K4: #NAME? | L4: 2 | M4: 2 | N4: 0 | Q4: 0 | R4: 0.1 | S4: =IFERROR(O4*E4,"") | T4: =IFERROR(P4*E4,"") | U4: =+M4*1800 -> 3600
B5: Chat | C5: Lunes | D5: 0.27083333 | E5: 1 | F5: 900 | G5: 2 | H5: 0.5 | I5: #NAME? | J5: 1 | K5: #NAME? | L5: 2 | M5: 2 | N5: 0 | O5: 0.8859058 | P5: 1 | Q5: 0.083333333 | R5: 0.1 | S5: =IFERROR(O5*E5,"") -> 0.8859058 | T5: =IFERROR(P5*E5,"") -> 1 | U5: =+M5*1800 -> 3600
B6: Chat | C6: Lunes | D6: 0.29166667 | E6: 3 | F6: 900 | G6: 2 | H6: 1.5 | I6: #NAME? | J6: 2 | K6: #NAME? | L6: 3 | M6: 2 | N6: -1 | O6: 0.68859053 | P6: 1 | Q6: 0.25 | R6: 0.1 | S6: =IFERROR(O6*E6,"") -> 2.0657716 | T6: =IFERROR(P6*E6,"") -> 3 | U6: =+M6*1800 -> 3600
B7: Chat | C7: Lunes | D7: 0.3125 | E7: 5 | F7: 900 | G7: 2 | H7: 2.5 | I7: #NAME? | J7: 2 | K7: #NAME? | L7: 3 | M7: 2 | N7: -1 | O7: 0.523476 | P7: 1 | Q7: 0.41666667 | R7: 0.1 | S7: =IFERROR(O7*E7,"") -> 2.61738 | T7: =IFERROR(P7*E7,"") -> 5 | U7: =+M7*1800 -> 3600
B8: Chat | C8: Lunes | D8: 0.33333333 | E8: 10 | F8: 900 | G8: 2 | H8: 5 | I8: #NAME? | J8: 3 | K8: #NAME? | L8: 4 | M8: 5 | N8: 1 | O8: 0.96253556 | P8: 1 | Q8: 0.33333333 | R8: 0.1 | S8: =IFERROR(O8*E8,"") -> 9.6253556 | T8: =IFERROR(P8*E8,"") -> 10 | U8: =+M8*1800 -> 9000
B9: Chat | C9: Lunes | D9: 0.35416667 | E9: 13 | F9: 900 | G9: 2 | H9: 6.5 | I9: #NAME? | J9: 4 | K9: #NAME? | L9: 5 | M9: 4.5 | N9: -0.5 | O9: 0.9106496 | P9: 1 | Q9: 0.48148148 | R9: 0.1 | S9: =IFERROR(O9*E9,"") -> 11.838445 | T9: =IFERROR(P9*E9,"") -> 13 | U9: =+M9*1800 -> 8100
B10: Chat | C10: Lunes | D10: 0.375 | E10: 8 | F10: 900 | G10: 2 | H10: 4 | I10: #NAME? | J10: 3 | K10: #NAME? | L10: 4 | M10: 6 | N10: 2 | O10: 0.99658841 | P10: 1 | Q10: 0.22222222 | R10: 0.1 | S10: =IFERROR(O10*E10,"") -> 7.9727073 | T10: =IFERROR(P10*E10,"") -> 8 | U10: =+M10*1800 -> 10800
B11: Chat | C11: Lunes | D11: 0.39583333 | E11: 19 | F11: 900 | G11: 2 | H11: 9.5 | I11: #NAME? | J11: 5 | K11: #NAME? | L11: 6 | M11: 5.5 | N11: -0.5 | O11: 0.78074133 | P11: 1 | Q11: 0.57575758 | R11: 0.1 | S11: =IFERROR(O11*E11,"") -> 14.834085 | T11: =IFERROR(P11*E11,"") -> 19 | U11: =+M11*1800 -> 9900
B12: Chat | C12: Lunes | D12: 0.41666667 | E12: 24 | F12: 900 | G12: 2 | H12: 12 | I12: #NAME? | J12: 6 | K12: #NAME? | L12: 7 | M12: 5 | N12: -2 | O12: 0.57651621 | P12: 0.93333333 | Q12: 0.8 | R12: 0.1 | S12: =IFERROR(O12*E12,"") -> 13.836389 | T12: =IFERROR(P12*E12,"") -> 22.4 | U12: =+M12*1800 -> 9000
B13: Chat | C13: Lunes | D13: 0.4375 | E13: 17 | F13: 900 | G13: 2 | H13: 8.5 | I13: #NAME? | J13: 4 | K13: #NAME? | L13: 5 | M13: 6.5 | N13: 1.5 | O13: 0.93784499 | P13: 0.94117647 | Q13: 0.43589744 | R13: 0.1 | S13: =IFERROR(O13*E13,"") -> 15.943365 | T13: =IFERROR(P13*E13,"") -> 16 | U13: =+M13*1800 -> 11700
B14: Chat | C14: Lunes | D14: 0.45833333 | E14: 23 | F14: 900 | G14: 2 | H14: 11.5 | I14: #NAME? | J14: 5 | K14: #NAME? | L14: 6 | M14: 8 | N14: 2 | O14: 0.97259116 | P14: 0.83478261 | Q14: 0.47916667 | R14: 0.1 | S14: =IFERROR(O14*E14,"") -> 22.369597 | T14: =IFERROR(P14*E14,"") -> 19.2 | U14: =+M14*1800 -> 14400
B15: Chat | C15: Lunes | D15: 0.47916667 | E15: 14 | F15: 900 | G15: 2 | H15: 7 | I15: #NAME? | J15: 4 | K15: #NAME? | L15: 5 | M15: 7.5 | N15: 2.5 | O15: 0.9916274 | P15: 1 | Q15: 0.31111111 | R15: 0.1 | S15: =IFERROR(O15*E15,"") -> 13.882784 | T15: =IFERROR(P15*E15,"") -> 14 | U15: =+M15*1800 -> 13500
B16: Chat | C16: Lunes | D16: 0.5 | E16: 15 | F16: 900 | G16: 2 | H16: 7.5 | I16: #NAME? | J16: 4 | K16: #NAME? | L16: 5 | M16: 6.5 | N16: 1.5 | O16: 0.96015948 | P16: 1 | Q16: 0.38461538 | R16: 0.1 | S16: =IFERROR(O16*E16,"") -> 14.402392 | T16: =IFERROR(P16*E16,"") -> 15 | U16: =+M16*1800 -> 11700
... B31: Chat | C31: Lunes | D31: 0.8125 | E31: 1 | F31: 900 | G31: 2 | H31: 0.5 | I31: #NAME? | J31: 1 | K31: #NAME? | L31: 2 | M31: 3 | N31: 1 | O31: 0.99317312 | P31: 1 | Q31: 0.055555556 | R31: 0.1 | S31: =IFERROR(O31*E31,"") -> 0.99317312 | T31: =IFERROR(P31*E31,"") -> 1 | U31: =+M31*1800 -> 5400
B32: Chat | C32: Lunes | D32: 0.83333333 | E32: 0 | F32: 0 | G32: 2 | H32: 0 | I32: #NAME? | J32: 1 | K32: #NAME? | L32: 2 | M32: 2 | N32: 0 | Q32: 0 | R32: 0.1 | S32: =IFERROR(O32*E32,"") | T32: =IFERROR(P32*E32,"") | U32: =+M32*1800 -> 3600
B33: Chat | C33: Lunes | D33: 0.85416667 | E33: 1 | F33: 900 | G33: 2 | H33: 0.5 | I33: #NAME? | J33: 1 | K33: #NAME? | L33: 2 | M33: 2 | N33: 0 | O33: 0.8859058 | P33: 1 | Q33: 0.083333333 | R33: 0.1 | S33: =IFERROR(O33*E33,"") -> 0.8859058 | T33: =IFERROR(P33*E33,"") -> 1 | U33: =+M33*1800 -> 3600
B34: Chat | C34: Lunes | D34: 0.875 | E34: 0 | F34: 0 | G34: 2 | H34: 0 | I34: #NAME? | J34: 1 | K34: #NAME? | L34: 2 | M34: 2 | N34: 0 | Q34: 0 | R34: 0.1 | S34: =IFERROR(O34*E34,"") | T34: =IFERROR(P34*E34,"") | U34: =+M34*1800 -> 3600
B35: Chat | C35: Lunes | D35: 0.89583333 | E35: 0 | F35: 0 | G35: 2 | H35: 0 | I35: #NAME? | J35: 1 | K35: #NAME? | L35: 2 | M35: 2 | N35: 0 | Q35: 0 | R35: 0.1 | S35: =IFERROR(O35*E35,"") | T35: =IFERROR(P35*E35,"") | U35: =+M35*1800 -> 3600
B36: Chat | C36: Martes | D36: 0.25 | E36: 0 | F36: 0 | G36: 2 | H36: 0 | I36: #NAME? | J36: 1 | K36: #NAME? | L36: 2 | M36: 2 | N36: 0 | Q36: 0 | R36: 0.1 | S36: =IFERROR(O36*E36,"") | T36: =IFERROR(P36*E36,"") | U36: =+M36*1800 -> 3600
B37: Chat | C37: Martes | D37: 0.27083333 | E37: 1 | F37: 900 | G37: 2 | H37: 0.5 | I37: #NAME? | J37: 1 | K37: #NAME? | L37: 2 | M37: 2 | N37: 0 | O37: 0.8859058 | P37: 1 | Q37: 0.083333333 | R37: 0.1 | S37: =IFERROR(O37*E37,"") -> 0.8859058 | T37: =IFERROR(P37*E37,"") -> 1 | U37: =+M37*1800 -> 3600
B38: Chat | C38: Martes | D38: 0.29166667 | E38: 3 | F38: 900 | G38: 2 | H38: 1.5 | I38: #NAME? | J38: 2 | K38: #NAME? | L38: 3 | M38: 2 | N38: -1 | O38: 0.68859053 | P38: 1 | Q38: 0.25 | R38: 0.1 | S38: =IFERROR(O38*E38,"") -> 2.0657716 | T38: =IFERROR(P38*E38,"") -> 3 | U38: =+M38*1800 -> 3600
B39: Chat | C39: Martes | D39: 0.3125 | E39: 5 | F39: 900 | G39: 2 | H39: 2.5 | I39: #NAME? | J39: 3 | K39: #NAME? | L39: 4 | M39: 2 | N39: -2 | O39: 0.523476 | P39: 1 | Q39: 0.41666667 | R39: 0.1 | S39: =IFERROR(O39*E39,"") -> 2.61738 | T39: =IFERROR(P39*E39,"") -> 5 | U39: =+M39*1800 -> 3600
B40: Chat | C40: Martes | D40: 0.33333333 | E40: 16 | F40: 900 | G40: 2 | H40: 8 | I40: #NAME? | J40: 5 | K40: #NAME? | L40: 6 | M40: 5 | N40: -1 | O40: 0.84931618 | P40: 1 | Q40: 0.53333333 | R40: 0.1 | S40: =IFERROR(O40*E40,"") -> 13.589059 | T40: =IFERROR(P40*E40,"") -> 16 | U40: =+M40*1800 -> 9000
B41: Chat | C41: Martes | D41: 0.35416667 | E41: 17 | F41: 900 | G41: 2 | H41: 8.5 | I41: #NAME? | J41: 5 | K41: #NAME? | L41: 6 | M41: 4.5 | N41: -1.5 | O41: 0.80470532 | P41: 0.98823529 | Q41: 0.62962963 | R41: 0.1 | S41: =IFERROR(O41*E41,"") -> 13.67999 | T41: =IFERROR(P41*E41,"") -> 16.8 | U41: =+M41*1800 -> 8100
B42: Chat | C42: Martes | D42: 0.375 | E42: 23 | F42: 900 | G42: 2 | H42: 11.5 | I42: #NAME? | J42: 7 | K42: #NAME? | L42: 8 | M42: 6 | N42: -2 | O42: 0.81930417 | P42: 0.97391304 | Q42: 0.63888889 | R42: 0.1 | S42: =IFERROR(O42*E42,"") -> 18.843996 | T42: =IFERROR(P42*E42,"") -> 22.4 | U42: =+M42*1800 -> 10800
B43: Chat | C43: Martes | D43: 0.39583333 | E43: 20 | F43: 900 | G43: 2 | H43: 10 | I43: #NAME? | J43: 6 | K43: #NAME? | L43: 7 | M43: 5.5 | N43: -1.5 | O43: 0.75121611 | P43: 0.98 | Q43: 0.60606061 | R43: 0.1 | S43: =IFERROR(O43*E43,"") -> 15.024322 | T43: =IFERROR(P43*E43,"") -> 19.6 | U43: =+M43*1800 -> 9900
B44: Chat | C44: Martes | D44: 0.41666667 | E44: 17 | F44: 900 | G44: 2 | H44: 8.5 | I44: #NAME? | J44: 5 | K44: #NAME? | L44: 6 | M44: 5 | N44: -1 | O44: 0.82226908 | P44: 0.98823529 | Q44: 0.56666667 | R44: 0.1 | S44: =IFERROR(O44*E44,"") -> 13.978574 | T44: =IFERROR(P44*E44,"") -> 16.8 | U44: =+M44*1800 -> 9000
B45: Chat | C45: Martes | D45: 0.4375 | E45: 20 | F45: 900 | G45: 2 | H45: 10 | I45: #NAME? | J45: 6 | K45: #NAME? | L45: 7 | M45: 6.5 | N45: -0.5 | O45: 0.89255768 | P45: 0.98 | Q45: 0.51282051 | R45: 0.1 | S45: =IFERROR(O45*E45,"") -> 17.851154 | T45: =IFERROR(P45*E45,"") -> 19.6 | U45: =+M45*1800 -> 11700
B46: Chat | C46: Martes | D46: 0.45833333 | E46: 22 | F46: 900 | G46: 2 | H46: 11 | I46: #NAME? | J46: 6 | K46: #NAME? | L46: 7 | M46: 8 | N46: 1 | O46: 0.97793233 | P46: 0.89090909 | Q46: 0.45833333 | R46: 0.1 | S46: =IFERROR(O46*E46,"") -> 21.514511 | T46: =IFERROR(P46*E46,"") -> 19.6 | U46: =+M46*1800 -> 14400
B47: Chat | C47: Martes | D47: 0.47916667 | E47: 16 | F47: 900 | G47: 2 | H47: 8 | I47: #NAME? | J47: 5 | K47: #NAME? | L47: 6 | M47: 7.5 | N47: 1.5 | O47: 0.9846257 | P47: 1 | Q47: 0.35555556 | R47: 0.1 | S47: =IFERROR(O47*E47,"") -> 15.754011 | T47: =IFERROR(P47*E47,"") -> 16 | U47: =+M47*1800 -> 13500
B48: Chat | C48: Martes | D48: 0.5 | E48: 13 | F48: 900 | G48: 2 | H48: 6.5 | I48: #NAME? | J48: 5 | K48: #NAME? | L48: 6 | M48: 6.5 | N48: 0.5 | O48: 0.97657794 | P48: 1 | Q48: 0.33333333 | R48: 0.1 | S48: =IFERROR(O48*E48,"") -> 12.695513 | T48: =IFERROR(P48*E48,"") -> 13 | U48: =+M48*1800 -> 11700
... B66: Chat | C66: Martes | D66: 0.875 | E66: 2 | F66: 900 | G66: 2 | H66: 1 | I66: #NAME? | J66: 2 | K66: #NAME? | L66: 3 | M66: 2 | N66: -1 | O66: 0.78261805 | P66: 1 | Q66: 0.16666667 | R66: 0.1 | S66: =IFERROR(O66*E66,"") -> 1.5652361 | T66: =IFERROR(P66*E66,"") -> 2 | U66: =+M66*1800 -> 3600
B67: Chat | C67: Martes | D67: 0.89583333 | E67: 0 | F67: 0 | G67: 2 | H67: 0 | I67: #NAME? | J67: 1 | K67: #NAME? | L67: 2 | M67: 2 | N67: 0 | Q67: 0 | R67: 0.1 | S67: =IFERROR(O67*E67,"") | T67: =IFERROR(P67*E67,"") | U67: =+M67*1800 -> 3600
B68: Chat | C68: Miércoles | D68: 0.25 | E68: 3 | F68: 900 | G68: 2 | H68: 1.5 | I68: #NAME? | J68: 2 | K68: #NAME? | L68: 3 | M68: 2 | N68: -1 | O68: 0.68859053 | P68: 1 | Q68: 0.25 | R68: 0.1 | S68: =IFERROR(O68*E68,"") -> 2.0657716 | T68: =IFERROR(P68*E68,"") -> 3 | U68: =+M68*1800 -> 3600
B69: Chat | C69: Miércoles | D69: 0.27083333 | E69: 0 | F69: 0 | G69: 2 | H69: 0 | I69: #NAME? | J69: 1 | K69: #NAME? | L69: 2 | M69: 2 | N69: 0 | Q69: 0 | R69: 0.1 | S69: =IFERROR(O69*E69,"") | T69: =IFERROR(P69*E69,"") | U69: =+M69*1800 -> 3600
B70: Chat | C70: Miércoles | D70: 0.29166667 | E70: 4 | F70: 900 | G70: 2 | H70: 2 | I70: #NAME? | J70: 2 | K70: #NAME? | L70: 3 | M70: 2 | N70: -1 | O70: 0.6025582 | P70: 1 | Q70: 0.33333333 | R70: 0.1 | S70: =IFERROR(O70*E70,"") -> 2.4102328 | T70: =IFERROR(P70*E70,"") -> 4 | U70: =+M70*1800 -> 3600
B71: Chat | C71: Miércoles | D71: 0.3125 | E71: 6 | F71: 900 | G71: 2 | H71: 3 | I71: #NAME? | J71: 3 | K71: #NAME? | L71: 4 | M71: 2 | N71: -2 | O71: 0.45047307 | P71: 1 | Q71: 0.5 | R71: 0.1 | S71: =IFERROR(O71*E71,"") -> 2.7028384 | T71: =IFERROR(P71*E71,"") -> 6 | U71: =+M71*1800 -> 3600
B72: Chat | C72: Miércoles | D72: 0.33333333 | E72: 19 | F72: 900 | G72: 2 | H72: 9.5 | I72: #NAME? | J72: 6 | K72: #NAME? | L72: 7 | M72: 5 | N72: -2 | O72: 0.76165861 | P72: 1 | Q72: 0.63333333 | R72: 0.1 | S72: =IFERROR(O72*E72,"") -> 14.471514 | T72: =IFERROR(P72*E72,"") -> 19 | U72: =+M72*1800 -> 9000
B73: Chat | C73: Miércoles | D73: 0.35416667 | E73: 21 | F73: 900 | G73: 2 | H73: 10.5 | I73: #NAME? | J73: 6 | K73: #NAME? | L73: 7 | M73: 4.5 | N73: -2.5 | O73: 0.65319806 | P73: 0.93333333 | Q73: 0.77777778 | R73: 0.1 | S73: =IFERROR(O73*E73,"") -> 13.717159 | T73: =IFERROR(P73*E73,"") -> 19.6 | U73: =+M73*1800 -> 8100
...
